Workbook

Sheet นิมนต์
G1: 2 | H1: 3 | I1: 4 | J1: 5 | K1: 6 | L1: 7 | M1: 8 | N1: 9
A2: ลำดับที่ | B2: ภาพ | C2: ลำดับสาขา | D2: ที่อยู่ | F2: ลำดับสาขา | G2: ชื่อวัด | H2: ชื่อพระ | I2: อายุอุปสมบท | J2: วันที่ | K2: เดือน | L2: พ.ศ. | M2: โทรศัพท์ | N2: ที่อยู่ | O2: พรรษา ปัจจุบัน | P2: นิมนต์ | Q2: อำเภอ | R2: จังหวัด | S2: For mappig | T2: For mappig
A3: 1 | C3: วัดบูรพาจารย์ | D3: วัดหนองป่าพง หมู่ที่ ๑๐ บ้านพงสว่าง ต.โนนผึ้ง อ.วารินชำราบ จ.อุบลราชธานี ๓๔๑๙๐ พระพรหมวชิรญาณโสภณ (เลี่ยม ฐิตธมฺโม) อุปสมบท เมื่ออาย ๒๐ ปี วันที่ ๒๒ เมษายน ๒๕๐๔ (ผู้รับรอง) - (๐๘๘) ๗๕๖-๕๐๕๗,- (๐๙๖) ๗๓๖-๘๖๘๓, | E3: =_xlfn.LET(_xlpm.x,C3, SUBSTITUTE(SUBSTITUTE(SUBSTITUTE(SUBSTITUTE(SUBSTITUTE( SUBSTITUTE(SUBSTITUTE(SUBSTITUTE(SUBSTITUTE(SUBSTITUTE( _xlpm.x,"๐","0"),"๑","1"),"๒","2"),"๓","3"),"๔","4"), "๕","5"),"๖","6"),"๗","7"),"๘","8"),"๙","9")) -> วัดบูรพาจารย์ | F3: 0 | G3: =_xlfn.TEXTBEFORE(D3,CHAR(10)) -> วัดหนองป่าพง | H3: =TRIM(_xlfn.TEXTBEFORE(MID(D3,SEARCH("พระ",D3),100),CHAR(10))) -> พระพรหมวชิรญาณโสภณ (เลี่ยม ฐิตธมฺโม) | I3: 20 | J3: 22 | K3: เมษายน | L3: 2504 | M3: =SUBSTITUTE(SUBSTITUTE(SUBSTITUTE(SUBSTITUTE(_xlfn.TEXTBEFORE(SUBSTITUTE(SUBSTITUTE(SUBSTITUTE(SUBSTITUTE(SUBSTITUTE(SUBSTITUTE(SUBSTITUTE(SUBSTITUTE(SUBSTITUTE(SUBSTITUTE(_xlfn.TEXTAFTER(D3,"- "),"๐","0"),"๑","1"),"๒","2"),"๓","3"),"๔","4"),"๕","5"),"๖","6"),"๗","7"),"๘","8"),"๙","9"),","),"(",""),")",""),"-","")," ","") -> #N/A | N3: =_xlfn.TEXTBEFORE(_xlfn.TEXTAFTER(D3,CHAR(10)),CHAR(10)&"พระ") -> หมู่ที่ ๑๐ บ้านพงสว่าง ต.โนนผึ้ง อ.วารินชำราบ จ.อุบลราชธานี ๓๔๑๙๐ | O3: =YEAR(TODAY())+543 - L3 -> 65 | P3: =VLOOKUP(T3,mapping!C:D,2,0) -> Y | Q3: =IFERROR("อ."&_xlfn.TEXTBEFORE(_xlfn.TEXTAFTER(N3,"อ.")," "),"") -> อ.วารินชำราบ | R3: =IFERROR("จ."&_xlfn.TEXTBEFORE(_xlfn.TEXTAFTER(N3,"จ.")," "),"") -> จ.อุบลราชธานี | S3: =IF(LEFT(C3,4)="สาขา","B", IF(LEFT(C3,4)="สำรอ","R", IF(LEFT(C3,4)="สำรว","S",0))) -> 0 | T3: =S3&F3 -> 00
A4: =+A3+1 -> 2 | C4: สาขาที่ ๐๐๘ | D4: วัดป่าโพธิญาณ (วัดเขื่อน) ๑๘๙ หมู่ ๑๒ บ้านดอนกลาง ต.ช่องเม็ก อ.สิรินธร จ.อุบลราชธานี ๓๔๓๕๐ พระครูโพธิสารคุณวัฒน์ (บุญชู ฐิตคุโณ) อุปสมบท เมื่ออายุ ๒๐ ปี วันที่ ๑๕ มีนาคม ๒๕๐๕ (ผู้รับรอง) -(๐๘๑) ๔๕๐-๐๔๖, (๐๘๑) ๓๙๓-๕๙๒๙ | E4: =_xlfn.LET(_xlpm.x,C4, SUBSTITUTE(SUBSTITUTE(SUBSTITUTE(SUBSTITUTE(SUBSTITUTE( SUBSTITUTE(SUBSTITUTE(SUBSTITUTE(SUBSTITUTE(SUBSTITUTE( _xlpm.x,"๐","0"),"๑","1"),"๒","2"),"๓","3"),"๔","4"), "๕","5"),"๖","6"),"๗","7"),"๘","8"),"๙","9")) -> สาขาที่ 008 | F4: 8 | G4: =_xlfn.TEXTBEFORE(D4,CHAR(10)) -> วัดป่าโพธิญาณ (วัดเขื่อน) | H4: =TRIM(_xlfn.TEXTBEFORE(MID(D4,SEARCH("พระ",D4),100),CHAR(10))) -> พระครูโพธิสารคุณวัฒน์ (บุญชู ฐิตคุโณ) | I4: =VALUE(SUBSTITUTE(SUBSTITUTE(SUBSTITUTE(SUBSTITUTE(SUBSTITUTE(SUBSTITUTE(SUBSTITUTE(SUBSTITUTE(SUBSTITUTE(SUBSTITUTE(_xlfn.TEXTBEFORE(_xlfn.TEXTAFTER(D4,"เมื่ออายุ "), " ปี"),"๐","0"),"๑","1"),"๒","2"),"๓","3"),"๔","4"),"๕","5"),"๖","6"),"๗","7"),"๘","8"),"๙","9")) -> 20 | J4: =VALUE(SUBSTITUTE(SUBSTITUTE(SUBSTITUTE(SUBSTITUTE(SUBSTITUTE(SUBSTITUTE(SUBSTITUTE(SUBSTITUTE(SUBSTITUTE(SUBSTITUTE(_xlfn.TEXTBEFORE(_xlfn.TEXTAFTER(D4,"วันที่ "), " "),"๐","0"),"๑","1"),"๒","2"),"๓","3"),"๔","4"),"๕","5"),"๖","6"),"๗","7"),"๘","8"),"๙","9")) -> 15 | K4: =_xlfn.TEXTBEFORE(_xlfn.TEXTAFTER(D4,"วันที่ "&_xlfn.TEXTBEFORE(_xlfn.TEXTAFTER(D4,"วันที่ "), " ")&" "), " ") -> มีนาคม | L4: =VALUE(SUBSTITUTE(SUBSTITUTE(SUBSTITUTE(SUBSTITUTE(SUBSTITUTE(SUBSTITUTE(SUBSTITUTE(SUBSTITUTE(SUBSTITUTE(SUBSTITUTE(_xlfn.TEXTBEFORE(_xlfn.TEXTAFTER(_xlfn.TEXTAFTER(D4,"วันที่ ")," "&_xlfn.TEXTBEFORE(_xlfn.TEXTAFTER(D4,"วันที่ "&_xlfn.TEXTBEFORE(_xlfn.TEXTAFTER(D4,"วันที่ "), " ")&" "), " ")&" "), " "),"๐","0"),"๑","1"),"๒","2"),"๓","3"),"๔","4"),"๕","5"),"๖","6"),"๗","7"),"๘","8"),"๙","9")) -> 2505 | M4: =SUBSTITUTE(SUBSTITUTE(SUBSTITUTE(SUBSTITUTE(_xlfn.TEXTBEFORE(SUBSTITUTE(SUBSTITUTE(SUBSTITUTE(SUBSTITUTE(SUBSTITUTE(SUBSTITUTE(SUBSTITUTE(SUBSTITUTE(SUBSTITUTE(SUBSTITUTE(_xlfn.TEXTAFTER(D4,"- "),"๐","0"),"๑","1"),"๒","2"),"๓","3"),"๔","4"),"๕","5"),"๖","6"),"๗","7"),"๘","8"),"๙","9"),","),"(",""),")",""),"-","")," ","") -> #N/A | N4: =_xlfn.TEXTBEFORE(_xlfn.TEXTAFTER(D4,CHAR(10)),CHAR(10)&"พระ") -> ๑๘๙ หมู่ ๑๒ บ้านดอนกลาง ต.ช่องเม็ก อ.สิรินธร จ.อุบลราชธานี ๓๔๓๕๐ | O4: =YEAR(TODAY())+543 - L4 -> 64 | P4: =VLOOKUP(T4,mapping!C:D,2,0) -> Y | Q4: =IFERROR("อ."&_xlfn.TEXTBEFORE(_xlfn.TEXTAFTER(N4,"อ.")," "),"") -> อ.สิรินธร | R4: =IFERROR("จ."&_xlfn.TEXTBEFORE(_xlfn.TEXTAFTER(N4,"จ.")," "),"") -> จ.อุบลราชธานี | S4: =IF(LEFT(C4,4)="สาขา","B", IF(LEFT(C4,4)="สำรอ","R", IF(LEFT(C4,4)="สำรว","S",0))) -> B | T4: =S4&F4 -> B8
A5: =+A4+1 -> 3 | C5: สาขาที่ ๐๒๖ | D5: วัดป่าโพธิ์สุวรรณ ๙๙ ม.๗ บ้านนาโพธิ์น้อย ต.นาโพธิ์น้อย อ.พิบูลมังสาหาร จ.อุบลราชธานี ๓๔๑๑๐ พระครูสุวรรณโพธิเขต (คูณ อคฺคธมฺโม) อุปสมบท เมื่ออายุ ๒๐ ปี วันที่ ๗ เมษายน ๒๕๐๙ (ผู้รับรอง) - (๐๘๐) ๔๗๕-๑๓๗๘,๐๔๕๓๘๔๐๖๖ | E5: =_xlfn.LET(_xlpm.x,C5, SUBSTITUTE(SUBSTITUTE(SUBSTITUTE(SUBSTITUTE(SUBSTITUTE( SUBSTITUTE(SUBSTITUTE(SUBSTITUTE(SUBSTITUTE(SUBSTITUTE( _xlpm.x,"๐","0"),"๑","1"),"๒","2"),"๓","3"),"๔","4"), "๕","5"),"๖","6"),"๗","7"),"๘","8"),"๙","9")) -> สาขาที่ 026 | F5: 26 | G5: =_xlfn.TEXTBEFORE(D5,CHAR(10)) -> วัดป่าโพธิ์สุวรรณ | H5: =TRIM(_xlfn.TEXTBEFORE(MID(D5,SEARCH("พระ",D5),100),CHAR(10))) -> พระครูสุวรรณโพธิเขต (คูณ อคฺคธมฺโม) | I5: =VALUE(SUBSTITUTE(SUBSTITUTE(SUBSTITUTE(SUBSTITUTE(SUBSTITUTE(SUBSTITUTE(SUBSTITUTE(SUBSTITUTE(SUBSTITUTE(SUBSTITUTE(_xlfn.TEXTBEFORE(_xlfn.TEXTAFTER(D5,"เมื่ออายุ "), " ปี"),"๐","0"),"๑","1"),"๒","2"),"๓","3"),"๔","4"),"๕","5"),"๖","6"),"๗","7"),"๘","8"),"๙","9")) -> 20 | J5: =VALUE(SUBSTITUTE(SUBSTITUTE(SUBSTITUTE(SUBSTITUTE(SUBSTITUTE(SUBSTITUTE(SUBSTITUTE(SUBSTITUTE(SUBSTITUTE(SUBSTITUTE(_xlfn.TEXTBEFORE(_xlfn.TEXTAFTER(D5,"วันที่ "), " "),"๐","0"),"๑","1"),"๒","2"),"๓","3"),"๔","4"),"๕","5"),"๖","6"),"๗","7"),"๘","8"),"๙","9")) -> 7 | K5: =_xlfn.TEXTBEFORE(_xlfn.TEXTAFTER(D5,"วันที่ "&_xlfn.TEXTBEFORE(_xlfn.TEXTAFTER(D5,"วันที่ "), " ")&" "), " ") -> เมษายน | L5: =VALUE(SUBSTITUTE(SUBSTITUTE(SUBSTITUTE(SUBSTITUTE(SUBSTITUTE(SUBSTITUTE(SUBSTITUTE(SUBSTITUTE(SUBSTITUTE(SUBSTITUTE(_xlfn.TEXTBEFORE(_xlfn.TEXTAFTER(_xlfn.TEXTAFTER(D5,"วันที่ ")," "&_xlfn.TEXTBEFORE(_xlfn.TEXTAFTER(D5,"วันที่ "&_xlfn.TEXTBEFORE(_xlfn.TEXTAFTER(D5,"วันที่ "), " ")&" "), " ")&" "), " "),"๐","0"),"๑","1"),"๒","2"),"๓","3"),"๔","4"),"๕","5"),"๖","6"),"๗","7"),"๘","8"),"๙","9")) -> 2509 | M5: =SUBSTITUTE(SUBSTITUTE(SUBSTITUTE(SUBSTITUTE(_xlfn.TEXTBEFORE(SUBSTITUTE(SUBSTITUTE(SUBSTITUTE(SUBSTITUTE(SUBSTITUTE(SUBSTITUTE(SUBSTITUTE(SUBSTITUTE(SUBSTITUTE(SUBSTITUTE(_xlfn.TEXTAFTER(D5,"- "),"๐","0"),"๑","1"),"๒","2"),"๓","3"),"๔","4"),"๕","5"),"๖","6"),"๗","7"),"๘","8"),"๙","9"),","),"(",""),")",""),"-","")," ","") -> 0804751378 | N5: =_xlfn.TEXTBEFORE(_xlfn.TEXTAFTER(D5,CHAR(10)),CHAR(10)&"พระ") -> ๙๙ ม.๗ บ้านนาโพธิ์น้อย ต.นาโพธิ์น้อย อ.พิบูลมังสาหาร จ.อุบลราชธานี ๓๔๑๑๐ | O5: =YEAR(TODAY())+543 - L5 -> 60 | P5: =VLOOKUP(T5,mapping!C:D,2,0) -> Y | Q5: =IFERROR("อ."&_xlfn.TEXTBEFORE(_xlfn.TEXTAFTER(N5,"อ.")," "),"") -> อ.พิบูลมังสาหาร | R5: =IFERROR("จ."&_xlfn.TEXTBEFORE(_xlfn.TEXTAFTER(N5,"จ.")," "),"") -> จ.อุบลราชธานี | S5: =IF(LEFT(C5,4)="สาขา","B", IF(LEFT(C5,4)="สำรอ","R", IF(LEFT(C5,4)="สำรว","S",0))) -> B | T5: =S5&F5 -> B26
A6: =+A5+1 -> 4 | C6: สาขาที่ ๐๒๙ | D6: วัดปลื้มพัฒนา ๗ หมู่ ๗ บ้านปลื้มพัฒนา ต.โคกมะม่วง อ.ปะคำ จ.บุรีรัมย์ ๓๑๒๒๐ พระครูภาวนาสารคุณ (ดำรง สุจิตฺโต) อุปสมบท เมื่ออายุ ๒๑ ปี วันที่ ๑๘ พฤษภาคม ๒๕๐๙ (ผู้รับรอง) ๐๘๑๙๗๖ ๑๒๘๙ | E6: =_xlfn.LET(_xlpm.x,C6, SUBSTITUTE(SUBSTITUTE(SUBSTITUTE(SUBSTITUTE(SUBSTITUTE( SUBSTITUTE(SUBSTITUTE(SUBSTITUTE(SUBSTITUTE(SUBSTITUTE( _xlpm.x,"๐","0"),"๑","1"),"๒","2"),"๓","3"),"๔","4"), "๕","5"),"๖","6"),"๗","7"),"๘","8"),"๙","9")) -> สาขาที่ 029 | F6: 29 | G6: =_xlfn.TEXTBEFORE(D6,CHAR(10)) -> วัดปลื้มพัฒนา | H6: =TRIM(_xlfn.TEXTBEFORE(MID(D6,SEARCH("พระ",D6),100),CHAR(10))) -> พระครูภาวนาสารคุณ (ดำรง สุจิตฺโต) | I6: =VALUE(SUBSTITUTE(SUBSTITUTE(SUBSTITUTE(SUBSTITUTE(SUBSTITUTE(SUBSTITUTE(SUBSTITUTE(SUBSTITUTE(SUBSTITUTE(SUBSTITUTE(_xlfn.TEXTBEFORE(_xlfn.TEXTAFTER(D6,"เมื่ออายุ "), " ปี"),"๐","0"),"๑","1"),"๒","2"),"๓","3"),"๔","4"),"๕","5"),"๖","6"),"๗","7"),"๘","8"),"๙","9")) -> 21 | J6: =VALUE(SUBSTITUTE(SUBSTITUTE(SUBSTITUTE(SUBSTITUTE(SUBSTITUTE(SUBSTITUTE(SUBSTITUTE(SUBSTITUTE(SUBSTITUTE(SUBSTITUTE(_xlfn.TEXTBEFORE(_xlfn.TEXTAFTER(D6,"วันที่ "), " "),"๐","0"),"๑","1"),"๒","2"),"๓","3"),"๔","4"),"๕","5"),"๖","6"),"๗","7"),"๘","8"),"๙","9")) -> 18 | K6: =_xlfn.TEXTBEFORE(_xlfn.TEXTAFTER(D6,"วันที่ "&_xlfn.TEXTBEFORE(_xlfn.TEXTAFTER(D6,"วันที่ "), " ")&" "), " ") -> พฤษภาคม | L6: =VALUE(SUBSTITUTE(SUBSTITUTE(SUBSTITUTE(SUBSTITUTE(SUBSTITUTE(SUBSTITUTE(SUBSTITUTE(SUBSTITUTE(SUBSTITUTE(SUBSTITUTE(_xlfn.TEXTBEFORE(_xlfn.TEXTAFTER(_xlfn.TEXTAFTER(D6,"วันที่ ")," "&_xlfn.TEXTBEFORE(_xlfn.TEXTAFTER(D6,"วันที่ "&_xlfn.TEXTBEFORE(_xlfn.TEXTAFTER(D6,"วันที่ "), " ")&" "), " ")&" "), " "),"๐","0"),"๑","1"),"๒","2"),"๓","3"),"๔","4"),"๕","5"),"๖","6"),"๗","7"),"๘","8"),"๙","9")) -> 2509 | M6: =SUBSTITUTE( _xlfn.TEXTBEFORE( SUBSTITUTE(SUBSTITUTE(SUBSTITUTE(SUBSTITUTE(SUBSTITUTE( SUBSTITUTE(SUBSTITUTE(SUBSTITUTE(SUBSTITUTE(SUBSTITUTE( _xlfn.TEXTAFTER(D6,CHAR(10),-1), "๐","0"),"๑","1"),"๒","2"),"๓","3"),"๔","4"), "๕","5"),"๖","6"),"๗","7"),"๘","8"),"๙","9"),",",-1)," ","") -> #N/A | N6: =_xlfn.TEXTBEFORE(_xlfn.TEXTAFTER(D6,CHAR(10)),CHAR(10)&"พระ") -> ๗ หมู่ ๗ บ้านปลื้มพัฒนา ต.โคกมะม่วง อ.ปะคำ จ.บุรีรัมย์ ๓๑๒๒๐ | O6: =YEAR(TODAY())+543 - L6 -> 60 | P6: =VLOOKUP(T6,mapping!C:D,2,0) -> Y | Q6: =IFERROR("อ."&_xlfn.TEXTBEFORE(_xlfn.TEXTAFTER(N6,"อ.")," "),"") -> อ.ปะคำ | R6: =IFERROR("จ."&_xlfn.TEXTBEFORE(_xlfn.TEXTAFTER(N6,"จ.")," "),"") -> จ.บุรีรัมย์ | S6: =IF(LEFT(C6,4)="สาขา","B", IF(LEFT(C6,4)="สำรอ","R", IF(LEFT(C6,4)="สำรว","S",0))) -> B | T6: =S6&F6 -> B29
A7: =+A6+1 -> 5 | C7: สาขาที่ ๐๓๕ | D7: วัดสุภัททมงคล ม.๙ บ้านยางเครือ ต.ยางสักกระโพหลุ่ม อ.ม่วงสามสิบ จ.อุบลราชธานี ๓๔๑๔๐ พระอธิการไพฑูรย์ ขนฺติโก อุปสมบท เมื่ออายุ ๒๑ ปี วันที่ ๒๗ พฤษภาคม ๒๕๐๙ (ผู้รับรอง) - (๐๘๕) ๘๕๘-๓๓๙๐ | E7: =_xlfn.LET(_xlpm.x,C7, SUBSTITUTE(SUBSTITUTE(SUBSTITUTE(SUBSTITUTE(SUBSTITUTE( SUBSTITUTE(SUBSTITUTE(SUBSTITUTE(SUBSTITUTE(SUBSTITUTE( _xlpm.x,"๐","0"),"๑","1"),"๒","2"),"๓","3"),"๔","4"), "๕","5"),"๖","6"),"๗","7"),"๘","8"),"๙","9")) -> สาขาที่ 035 | F7: 35 | G7: =_xlfn.TEXTBEFORE(D7,CHAR(10)) -> วัดสุภัททมงคล | H7: =TRIM(_xlfn.TEXTBEFORE(MID(D7,SEARCH("พระ",D7),100),CHAR(10))) -> พระอธิการไพฑูรย์ ขนฺติโก | I7: =VALUE(SUBSTITUTE(SUBSTITUTE(SUBSTITUTE(SUBSTITUTE(SUBSTITUTE(SUBSTITUTE(SUBSTITUTE(SUBSTITUTE(SUBSTITUTE(SUBSTITUTE(_xlfn.TEXTBEFORE(_xlfn.TEXTAFTER(D7,"เมื่ออายุ "), " ปี"),"๐","0"),"๑","1"),"๒","2"),"๓","3"),"๔","4"),"๕","5"),"๖","6"),"๗","7"),"๘","8"),"๙","9")) -> 21 | J7: =VALUE(SUBSTITUTE(SUBSTITUTE(SUBSTITUTE(SUBSTITUTE(SUBSTITUTE(SUBSTITUTE(SUBSTITUTE(SUBSTITUTE(SUBSTITUTE(SUBSTITUTE(_xlfn.TEXTBEFORE(_xlfn.TEXTAFTER(D7,"วันที่ "), " "),"๐","0"),"๑","1"),"๒","2"),"๓","3"),"๔","4"),"๕","5"),"๖","6"),"๗","7"),"๘","8"),"๙","9")) -> 27 | K7: =_xlfn.TEXTBEFORE(_xlfn.TEXTAFTER(D7,"วันที่ "&_xlfn.TEXTBEFORE(_xlfn.TEXTAFTER(D7,"วันที่ "), " ")&" "), " ") -> พฤษภาคม | L7: =VALUE(SUBSTITUTE(SUBSTITUTE(SUBSTITUTE(SUBSTITUTE(SUBSTITUTE(SUBSTITUTE(SUBSTITUTE(SUBSTITUTE(SUBSTITUTE(SUBSTITUTE(_xlfn.TEXTBEFORE(_xlfn.TEXTAFTER(_xlfn.TEXTAFTER(D7,"วันที่ ")," "&_xlfn.TEXTBEFORE(_xlfn.TEXTAFTER(D7,"วันที่ "&_xlfn.TEXTBEFORE(_xlfn.TEXTAFTER(D7,"วันที่ "), " ")&" "), " ")&" "), " "),"๐","0"),"๑","1"),"๒","2"),"๓","3"),"๔","4"),"๕","5"),"๖","6"),"๗","7"),"๘","8"),"๙","9")) -> 2509 | M7: =SUBSTITUTE(SUBSTITUTE(SUBSTITUTE(SUBSTITUTE(_xlfn.TEXTBEFORE(SUBSTITUTE(SUBSTITUTE(SUBSTITUTE(SUBSTITUTE(SUBSTITUTE(SUBSTITUTE(SUBSTITUTE(SUBSTITUTE(SUBSTITUTE(SUBSTITUTE(_xlfn.TEXTAFTER(D7,"- "),"๐","0"),"๑","1"),"๒","2"),"๓","3"),"๔","4"),"๕","5"),"๖","6"),"๗","7"),"๘","8"),"๙","9"),","),"(",""),")",""),"-","")," ","") -> #N/A | N7: =_xlfn.TEXTBEFORE(_xlfn.TEXTAFTER(D7,CHAR(10)),CHAR(10)&"พระ") -> ม.๙ บ้านยางเครือ ต.ยางสักกระโพหลุ่ม อ.ม่วงสามสิบ จ.อุบลราชธานี ๓๔๑๔๐ | O7: =YEAR(TODAY())+543 - L7 -> 60 | P7: =VLOOKUP(T7,mapping!C:D,2,0) -> Y | Q7: =IFERROR("อ."&_xlfn.TEXTBEFORE(_xlfn.TEXTAFTER(N7,"อ.")," "),"") -> อ.ม่วงสามสิบ | R7: =IFERROR("จ."&_xlfn.TEXTBEFORE(_xlfn.TEXTAFTER(N7,"จ.")," "),"") -> จ.อุบลราชธานี | S7: =IF(LEFT(C7,4)="สาขา","B", IF(LEFT(C7,4)="สำรอ","R", IF(LEFT(C7,4)="สำรว","S",0))) -> B | T7: =S7&F7 -> B35
A8: =+A7+1 -> 6 | C8: สาขาที่ ๐๖๖ | D8: วัดป่าโนนโศกเสือ ๑๔๓ ม.๙ บ้านโคกสะอาด ต.หนองฮะ อ.สำโรงทาบ จ.สุรินทร์ ๓๒๑๗๐ พระอธิการนำ ปญฺญาวโร อุปสมบท เมื่ออายุ ๒๐ ปี วันที่ ๓ มิถุนายน ๒๕๐๙ (ผู้รับรอง) - (๐๘๐) ๑๒๐-๙๑๐๒ | E8: =_xlfn.LET(_xlpm.x,C8, SUBSTITUTE(SUBSTITUTE(SUBSTITUTE(SUBSTITUTE(SUBSTITUTE( SUBSTITUTE(SUBSTITUTE(SUBSTITUTE(SUBSTITUTE(SUBSTITUTE( _xlpm.x,"๐","0"),"๑","1"),"๒","2"),"๓","3"),"๔","4"), "๕","5"),"๖","6"),"๗","7"),"๘","8"),"๙","9")) -> สาขาที่ 066 | F8: 66 | G8: =_xlfn.TEXTBEFORE(D8,CHAR(10)) -> วัดป่าโนนโศกเสือ | H8: =TRIM(_xlfn.TEXTBEFORE(MID(D8,SEARCH("พระ",D8),100),CHAR(10))) -> พระอธิการนำ ปญฺญาวโร | I8: =VALUE(SUBSTITUTE(SUBSTITUTE(SUBSTITUTE(SUBSTITUTE(SUBSTITUTE(SUBSTITUTE(SUBSTITUTE(SUBSTITUTE(SUBSTITUTE(SUBSTITUTE(_xlfn.TEXTBEFORE(_xlfn.TEXTAFTER(D8,"เมื่ออายุ "), " ปี"),"๐","0"),"๑","1"),"๒","2"),"๓","3"),"๔","4"),"๕","5"),"๖","6"),"๗","7"),"๘","8"),"๙","9")) -> 20 | J8: =VALUE(SUBSTITUTE(SUBSTITUTE(SUBSTITUTE(SUBSTITUTE(SUBSTITUTE(SUBSTITUTE(SUBSTITUTE(SUBSTITUTE(SUBSTITUTE(SUBSTITUTE(_xlfn.TEXTBEFORE(_xlfn.TEXTAFTER(D8,"วันที่ "), " "),"๐","0"),"๑","1"),"๒","2"),"๓","3"),"๔","4"),"๕","5"),"๖","6"),"๗","7"),"๘","8"),"๙","9")) -> 3 | K8: =_xlfn.TEXTBEFORE(_xlfn.TEXTAFTER(D8,"วันที่ "&_xlfn.TEXTBEFORE(_xlfn.TEXTAFTER(D8,"วันที่ "), " ")&" "), " ") -> มิถุนายน | L8: =VALUE(SUBSTITUTE(SUBSTITUTE(SUBSTITUTE(SUBSTITUTE(SUBSTITUTE(SUBSTITUTE(SUBSTITUTE(SUBSTITUTE(SUBSTITUTE(SUBSTITUTE(_xlfn.TEXTBEFORE(_xlfn.TEXTAFTER(_xlfn.TEXTAFTER(D8,"วันที่ ")," "&_xlfn.TEXTBEFORE(_xlfn.TEXTAFTER(D8,"วันที่ "&_xlfn.TEXTBEFORE(_xlfn.TEXTAFTER(D8,"วันที่ "), " ")&" "), " ")&" "), " "),"๐","0"),"๑","1"),"๒","2"),"๓","3"),"๔","4"),"๕","5"),"๖","6"),"๗","7"),"๘","8"),"๙","9")) -> 2509 | M8: =SUBSTITUTE(SUBSTITUTE(SUBSTITUTE(SUBSTITUTE(_xlfn.TEXTBEFORE(SUBSTITUTE(SUBSTITUTE(SUBSTITUTE(SUBSTITUTE(SUBSTITUTE(SUBSTITUTE(SUBSTITUTE(SUBSTITUTE(SUBSTITUTE(SUBSTITUTE(_xlfn.TEXTAFTER(D8,"- "),"๐","0"),"๑","1"),"๒","2"),"๓","3"),"๔","4"),"๕","5"),"๖","6"),"๗","7"),"๘","8"),"๙","9"),","),"(",""),")",""),"-","")," ","") -> #N/A | N8: =_xlfn.TEXTBEFORE(_xlfn.TEXTAFTER(D8,CHAR(10)),CHAR(10)&"พระ") -> ๑๔๓ ม.๙ บ้านโคกสะอาด ต.หนองฮะ อ.สำโรงทาบ จ.สุรินทร์ ๓๒๑๗๐ | O8: =YEAR(TODAY())+543 - L8 -> 60 | P8: =VLOOKUP(T8,mapping!C:D,2,0) -> Y | Q8: =IFERROR("อ."&_xlfn.TEXTBEFORE(_xlfn.TEXTAFTER(N8,"อ.")," "),"") -> อ.สำโรงทาบ | R8: =IFERROR("จ."&_xlfn.TEXTBEFORE(_xlfn.TEXTAFTER(N8,"จ.")," "),"") -> จ.สุรินทร์ | S8: =IF(LEFT(C8,4)="สาขา","B", IF(LEFT(C8,4)="สำรอ","R", IF(LEFT(C8,4)="สำรว","S",0))) -> B | T8: =S8&F8 -> B66
A9: =+A8+1 -> 7 | C9: สาขาที่ ๐๑๐ | D9: วัดป่าไทรงาม ๓๙๕ หมู่ ๓๕ บ้านทุ่งไทรงาม ต.เมืองเดช อ.เดชอุดม จ.อุบลราชธานี ๓๔๑๖๐ พระราชภาวนาวัชรมุนี (เอนก ยสทินฺโน) อุปสมบท เมื่ออายุ ๒๐ ปี วันที่ ๙ มิถุนายน ๒๕๑๐ (ผู้รับรอง) ๐๘๖๗๘๙ ๗๙๓๙,๐๘๑๙๙๗ ๗๕๘๒ | E9: =_xlfn.LET(_xlpm.x,C9, SUBSTITUTE(SUBSTITUTE(SUBSTITUTE(SUBSTITUTE(SUBSTITUTE( SUBSTITUTE(SUBSTITUTE(SUBSTITUTE(SUBSTITUTE(SUBSTITUTE( _xlpm.x,"๐","0"),"๑","1"),"๒","2"),"๓","3"),"๔","4"), "๕","5"),"๖","6"),"๗","7"),"๘","8"),"๙","9")) -> สาขาที่ 010 | F9: 10 | G9: =_xlfn.TEXTBEFORE(D9,CHAR(10)) -> วัดป่าไทรงาม | H9: =TRIM(_xlfn.TEXTBEFORE(MID(D9,SEARCH("พระ",D9),100),CHAR(10))) -> พระราชภาวนาวัชรมุนี (เอนก ยสทินฺโน) | I9: =VALUE(SUBSTITUTE(SUBSTITUTE(SUBSTITUTE(SUBSTITUTE(SUBSTITUTE(SUBSTITUTE(SUBSTITUTE(SUBSTITUTE(SUBSTITUTE(SUBSTITUTE(_xlfn.TEXTBEFORE(_xlfn.TEXTAFTER(D9,"เมื่ออายุ "), " ปี"),"๐","0"),"๑","1"),"๒","2"),"๓","3"),"๔","4"),"๕","5"),"๖","6"),"๗","7"),"๘","8"),"๙","9")) -> 20 | J9: =VALUE(SUBSTITUTE(SUBSTITUTE(SUBSTITUTE(SUBSTITUTE(SUBSTITUTE(SUBSTITUTE(SUBSTITUTE(SUBSTITUTE(SUBSTITUTE(SUBSTITUTE(_xlfn.TEXTBEFORE(_xlfn.TEXTAFTER(D9,"วันที่ "), " "),"๐","0"),"๑","1"),"๒","2"),"๓","3"),"๔","4"),"๕","5"),"๖","6"),"๗","7"),"๘","8"),"๙","9")) -> 9 | K9: =_xlfn.TEXTBEFORE(_xlfn.TEXTAFTER(D9,"วันที่ "&_xlfn.TEXTBEFORE(_xlfn.TEXTAFTER(D9,"วันที่ "), " ")&" "), " ") -> มิถุนายน | L9: =VALUE(SUBSTITUTE(SUBSTITUTE(SUBSTITUTE(SUBSTITUTE(SUBSTITUTE(SUBSTITUTE(SUBSTITUTE(SUBSTITUTE(SUBSTITUTE(SUBSTITUTE(_xlfn.TEXTBEFORE(_xlfn.TEXTAFTER(_xlfn.TEXTAFTER(D9,"วันที่ ")," "&_xlfn.TEXTBEFORE(_xlfn.TEXTAFTER(D9,"วันที่ "&_xlfn.TEXTBEFORE(_xlfn.TEXTAFTER(D9,"วันที่ "), " ")&" "), " ")&" "), " "),"๐","0"),"๑","1"),"๒","2"),"๓","3"),"๔","4"),"๕","5"),"๖","6"),"๗","7"),"๘","8"),"๙","9")) -> 2510 | M9: =SUBSTITUTE( _xlfn.TEXTBEFORE( SUBSTITUTE(SUBSTITUTE(SUBSTITUTE(SUBSTITUTE(SUBSTITUTE( SUBSTITUTE(SUBSTITUTE(SUBSTITUTE(SUBSTITUTE(SUBSTITUTE( _xlfn.TEXTAFTER(D9,CHAR(10),-1), "๐","0"),"๑","1"),"๒","2"),"๓","3"),"๔","4"), "๕","5"),"๖","6"),"๗","7"),"๘","8"),"๙","9"),",",-1)," ","") -> 0867897939 | N9: =_xlfn.TEXTBEFORE(_xlfn.TEXTAFTER(D9,CHAR(10)),CHAR(10)&"พระ") -> ๓๙๕ หมู่ ๓๕ บ้านทุ่งไทรงาม ต.เมืองเดช อ.เดชอุดม จ.อุบลราชธานี ๓๔๑๖๐ | O9: =YEAR(TODAY())+543 - L9 -> 59 | P9: =VLOOKUP(T9,mapping!C:D,2,0) -> Y | Q9: =IFERROR("อ."&_xlfn.TEXTBEFORE(_xlfn.TEXTAFTER(N9,"อ.")," "),"") -> อ.เดชอุดม | R9: =IFERROR("จ."&_xlfn.TEXTBEFORE(_xlfn.TEXTAFTER(N9,"จ.")," "),"") -> จ.อุบลราชธานี | S9: =IF(LEFT(C9,4)="สาขา","B", IF(LEFT(C9,4)="สำรอ","R", IF(LEFT(C9,4)="สำรว","S",0))) -> B | T9: =S9&F9 -> B10
A10: =+A9+1 -> 8 | C10: สาขาที่ ๐๓๐ | D10: วัดอุดมวารี ๕๑๓ ม.๑๐ บ้านโป่งแดง ต.ทรายขาว อ.พาน จ.เชียงราย ๕๗๑๒๐ พระครูอุดมวีรวัฒน์ (คูณ ติกฺขวีโร) อุปสมบท เมื่ออายุ ๒๔ ปี วันที่ ๕ พฤษภาคม ๒๕๑๐ (ผู้รับรอง) - (๐๘๑) ๙๘๙-๕๑๒๔,- (๐๘๑) ๗๑๐-๐๑๑๙, | E10: =_xlfn.LET(_xlpm.x,C10, SUBSTITUTE(SUBSTITUTE(SUBSTITUTE(SUBSTITUTE(SUBSTITUTE( SUBSTITUTE(SUBSTITUTE(SUBSTITUTE(SUBSTITUTE(SUBSTITUTE( _xlpm.x,"๐","0"),"๑","1"),"๒","2"),"๓","3"),"๔","4"), "๕","5"),"๖","6"),"๗","7"),"๘","8"),"๙","9")) -> สาขาที่ 030 | F10: 30 | G10: =_xlfn.TEXTBEFORE(D10,CHAR(10)) -> วัดอุดมวารี | H10: =TRIM(_xlfn.TEXTBEFORE(MID(D10,SEARCH("พระ",D10),100),CHAR(10))) -> พระครูอุดมวีรวัฒน์ (คูณ ติกฺขวีโร) | I10: =VALUE(SUBSTITUTE(SUBSTITUTE(SUBSTITUTE(SUBSTITUTE(SUBSTITUTE(SUBSTITUTE(SUBSTITUTE(SUBSTITUTE(SUBSTITUTE(SUBSTITUTE(_xlfn.TEXTBEFORE(_xlfn.TEXTAFTER(D10,"เมื่ออายุ "), " ปี"),"๐","0"),"๑","1"),"๒","2"),"๓","3"),"๔","4"),"๕","5"),"๖","6"),"๗","7"),"๘","8"),"๙","9")) -> 24 | J10: =VALUE(SUBSTITUTE(SUBSTITUTE(SUBSTITUTE(SUBSTITUTE(SUBSTITUTE(SUBSTITUTE(SUBSTITUTE(SUBSTITUTE(SUBSTITUTE(SUBSTITUTE(_xlfn.TEXTBEFORE(_xlfn.TEXTAFTER(D10,"วันที่ "), " "),"๐","0"),"๑","1"),"๒","2"),"๓","3"),"๔","4"),"๕","5"),"๖","6"),"๗","7"),"๘","8"),"๙","9")) -> 5 | K10: =_xlfn.TEXTBEFORE(_xlfn.TEXTAFTER(D10,"วันที่ "&_xlfn.TEXTBEFORE(_xlfn.TEXTAFTER(D10,"วันที่ "), " ")&" "), " ") -> พฤษภาคม | L10: =VALUE(SUBSTITUTE(SUBSTITUTE(SUBSTITUTE(SUBSTITUTE(SUBSTITUTE(SUBSTITUTE(SUBSTITUTE(SUBSTITUTE(SUBSTITUTE(SUBSTITUTE(_xlfn.TEXTBEFORE(_xlfn.TEXTAFTER(_xlfn.TEXTAFTER(D10,"วันที่ ")," "&_xlfn.TEXTBEFORE(_xlfn.TEXTAFTER(D10,"วันที่ "&_xlfn.TEXTBEFORE(_xlfn.TEXTAFTER(D10,"วันที่ "), " ")&" "), " ")&" "), " "),"๐","0"),"๑","1"),"๒","2"),"๓","3"),"๔","4"),"๕","5"),"๖","6"),"๗","7"),"๘","8"),"๙","9")) -> 2510 | M10: =SUBSTITUTE(SUBSTITUTE(SUBSTITUTE(SUBSTITUTE(_xlfn.TEXTBEFORE(SUBSTITUTE(SUBSTITUTE(SUBSTITUTE(SUBSTITUTE(SUBSTITUTE(SUBSTITUTE(SUBSTITUTE(SUBSTITUTE(SUBSTITUTE(SUBSTITUTE(_xlfn.TEXTAFTER(D10,"- "),"๐","0"),"๑","1"),"๒","2"),"๓","3"),"๔","4"),"๕","5"),"๖","6"),"๗","7"),"๘","8"),"๙","9"),","),"(",""),")",""),"-","")," ","") -> 0819895124 | N10: =_xlfn.TEXTBEFORE(_xlfn.TEXTAFTER(D10,CHAR(10)),CHAR(10)&"พระ") -> ๕๑๓ ม.๑๐ บ้านโป่งแดง ต.ทรายขาว อ.พาน จ.เชียงราย ๕๗๑๒๐ | O10: =YEAR(TODAY())+543 - L10 -> 59 | P10: =VLOOKUP(T10,mapping!C:D,2,0) -> Y | Q10: =IFERROR("อ."&_xlfn.TEXTBEFORE(_xlfn.TEXTAFTER(N10,"อ.")," "),"") -> อ.พาน | R10: =IFERROR("จ."&_xlfn.TEXTBEFORE(_xlfn.TEXTAFTER(N10,"จ.")," "),"") -> จ.เชียงราย | S10: =IF(LEFT(C10,4)="สาขา","B", IF(LEFT(C10,4)="สำรอ","R", IF(LEFT(C10,4)="สำรว","S",0))) -> B | T10: =S10&F10 -> B30
A11: =+A10+1 -> 9 | C11: สาขาที่ ๐๒๐ | D11: วัดบึงลัฏฐิวัน ๒๖ หมู่ ๑ บ้านช้าง ต.ท่าหลวง อ.ท่าเรือ จ.พระนครศรีอยุธยา ๑๘๒๗๐ พระครูโอภาสวุฒิกร (โสภณ โอภาโส) อุปสมบท เมื่ออายุ ๒๓ ปี วันที่ ๑๐ มิถุนายน ๒๕๑๑ (ผู้รับรอง) - (๐๘๙) ๒๐๑-๑๔๗๔,๐๓๕๓๔๑๘๓๙, | E11: =_xlfn.LET(_xlpm.x,C11, SUBSTITUTE(SUBSTITUTE(SUBSTITUTE(SUBSTITUTE(SUBSTITUTE( SUBSTITUTE(SUBSTITUTE(SUBSTITUTE(SUBSTITUTE(SUBSTITUTE( _xlpm.x,"๐","0"),"๑","1"),"๒","2"),"๓","3"),"๔","4"), "๕","5"),"๖","6"),"๗","7"),"๘","8"),"๙","9")) -> สาขาที่ 020 | F11: 20 | G11: =_xlfn.TEXTBEFORE(D11,CHAR(10)) -> วัดบึงลัฏฐิวัน | H11: =TRIM(_xlfn.TEXTBEFORE(MID(D11,SEARCH("พระค",D11),100),CHAR(10))) -> พระครูโอภาสวุฒิกร (โสภณ โอภาโส) | I11: =VALUE(SUBSTITUTE(SUBSTITUTE(SUBSTITUTE(SUBSTITUTE(SUBSTITUTE(SUBSTITUTE(SUBSTITUTE(SUBSTITUTE(SUBSTITUTE(SUBSTITUTE(_xlfn.TEXTBEFORE(_xlfn.TEXTAFTER(D11,"เมื่ออายุ "), " ปี"),"๐","0"),"๑","1"),"๒","2"),"๓","3"),"๔","4"),"๕","5"),"๖","6"),"๗","7"),"๘","8"),"๙","9")) -> 23 | J11: =VALUE(SUBSTITUTE(SUBSTITUTE(SUBSTITUTE(SUBSTITUTE(SUBSTITUTE(SUBSTITUTE(SUBSTITUTE(SUBSTITUTE(SUBSTITUTE(SUBSTITUTE(_xlfn.TEXTBEFORE(_xlfn.TEXTAFTER(D11,"วันที่ "), " "),"๐","0"),"๑","1"),"๒","2"),"๓","3"),"๔","4"),"๕","5"),"๖","6"),"๗","7"),"๘","8"),"๙","9")) -> 10 | K11: =_xlfn.TEXTBEFORE(_xlfn.TEXTAFTER(D11,"วันที่ "&_xlfn.TEXTBEFORE(_xlfn.TEXTAFTER(D11,"วันที่ "), " ")&" "), " ") -> มิถุนายน | L11: =VALUE(SUBSTITUTE(SUBSTITUTE(SUBSTITUTE(SUBSTITUTE(SUBSTITUTE(SUBSTITUTE(SUBSTITUTE(SUBSTITUTE(SUBSTITUTE(SUBSTITUTE(_xlfn.TEXTBEFORE(_xlfn.TEXTAFTER(_xlfn.TEXTAFTER(D11,"วันที่ ")," "&_xlfn.TEXTBEFORE(_xlfn.TEXTAFTER(D11,"วันที่ "&_xlfn.TEXTBEFORE(_xlfn.TEXTAFTER(D11,"วันที่ "), " ")&" "), " ")&" "), " "),"๐","0"),"๑","1"),"๒","2"),"๓","3"),"๔","4"),"๕","5"),"๖","6"),"๗","7"),"๘","8"),"๙","9")) -> 2511 | M11: =SUBSTITUTE(SUBSTITUTE(SUBSTITUTE(SUBSTITUTE(_xlfn.TEXTBEFORE(SUBSTITUTE(SUBSTITUTE(SUBSTITUTE(SUBSTITUTE(SUBSTITUTE(SUBSTITUTE(SUBSTITUTE(SUBSTITUTE(SUBSTITUTE(SUBSTITUTE(_xlfn.TEXTAFTER(D11,"- "),"๐","0"),"๑","1"),"๒","2"),"๓","3"),"๔","4"),"๕","5"),"๖","6"),"๗","7"),"๘","8"),"๙","9"),","),"(",""),")",""),"-","")," ","") -> 0892011474 | N11: =_xlfn.TEXTBEFORE(_xlfn.TEXTAFTER(D11,CHAR(10)),CHAR(10)&"พระ") -> ๒๖ หมู่ ๑ บ้านช้าง ต.ท่าหลวง อ.ท่าเรือ จ.พระนครศรีอยุธยา ๑๘๒๗๐ | O11: =YEAR(TODAY())+543 - L11 -> 58 | P11: =VLOOKUP(T11,mapping!C:D,2,0) -> Y | Q11: =IFERROR("อ."&_xlfn.TEXTBEFORE(_xlfn.TEXTAFTER(N11,"อ.")," "),"") -> อ.ท่าเรือ | R11: =IFERROR("จ."&_xlfn.TEXTBEFORE(_xlfn.TEXTAFTER(N11,"จ.")," "),"") -> จ.พระนครศรีอยุธยา | S11: =IF(LEFT(C11,4)="สาขา","B", IF(LEFT(C11,4)="สำรอ","R", IF(LEFT(C11,4)="สำรว","S",0))) -> B | T11: =S11&F11 -> B20
A12: =+A11+1 -> 10 | C12: สาขาที่ ๐๒๕ | D12: วัดป่าน้ำคำเกิ่ง ม.๙ บ้านคำเกิ่ง ต.เตย อ.ม่วงสามสิบ จ.อุบลราชธานี ๓๔๑๔๐ พระครูภัทรธรรมสิริ (ดำรง สิริภทฺโท) อุปสมบท เมื่ออายุ ๒๐ ปี วันที่ ๑๓ เมษายน ๒๕๑๒ (ผู้รับรอง) - (๐๘๑) ๙๙๗-๖๑๖๐, | E12: =_xlfn.LET(_xlpm.x,C12, SUBSTITUTE(SUBSTITUTE(SUBSTITUTE(SUBSTITUTE(SUBSTITUTE( SUBSTITUTE(SUBSTITUTE(SUBSTITUTE(SUBSTITUTE(SUBSTITUTE( _xlpm.x,"๐","0"),"๑","1"),"๒","2"),"๓","3"),"๔","4"), "๕","5"),"๖","6"),"๗","7"),"๘","8"),"๙","9")) -> สาขาที่ 025 | F12: 25 | G12: =_xlfn.TEXTBEFORE(D12,CHAR(10)) -> วัดป่าน้ำคำเกิ่ง | H12: =TRIM(_xlfn.TEXTBEFORE(MID(D12,SEARCH("พระ",D12),100),CHAR(10))) -> พระครูภัทรธรรมสิริ (ดำรง สิริภทฺโท) | I12: =VALUE(SUBSTITUTE(SUBSTITUTE(SUBSTITUTE(SUBSTITUTE(SUBSTITUTE(SUBSTITUTE(SUBSTITUTE(SUBSTITUTE(SUBSTITUTE(SUBSTITUTE(_xlfn.TEXTBEFORE(_xlfn.TEXTAFTER(D12,"เมื่ออายุ "), " ปี"),"๐","0"),"๑","1"),"๒","2"),"๓","3"),"๔","4"),"๕","5"),"๖","6"),"๗","7"),"๘","8"),"๙","9")) -> 20 | J12: =VALUE(SUBSTITUTE(SUBSTITUTE(SUBSTITUTE(SUBSTITUTE(SUBSTITUTE(SUBSTITUTE(SUBSTITUTE(SUBSTITUTE(SUBSTITUTE(SUBSTITUTE(_xlfn.TEXTBEFORE(_xlfn.TEXTAFTER(D12,"วันที่ "), " "),"๐","0"),"๑","1"),"๒","2"),"๓","3"),"๔","4"),"๕","5"),"๖","6"),"๗","7"),"๘","8"),"๙","9")) -> 13 | K12: =_xlfn.TEXTBEFORE(_xlfn.TEXTAFTER(D12,"วันที่ "&_xlfn.TEXTBEFORE(_xlfn.TEXTAFTER(D12,"วันที่ "), " ")&" "), " ") -> เมษายน | L12: =VALUE(SUBSTITUTE(SUBSTITUTE(SUBSTITUTE(SUBSTITUTE(SUBSTITUTE(SUBSTITUTE(SUBSTITUTE(SUBSTITUTE(SUBSTITUTE(SUBSTITUTE(_xlfn.TEXTBEFORE(_xlfn.TEXTAFTER(_xlfn.TEXTAFTER(D12,"วันที่ ")," "&_xlfn.TEXTBEFORE(_xlfn.TEXTAFTER(D12,"วันที่ "&_xlfn.TEXTBEFORE(_xlfn.TEXTAFTER(D12,"วันที่ "), " ")&" "), " ")&" "), " "),"๐","0"),"๑","1"),"๒","2"),"๓","3"),"๔","4"),"๕","5"),"๖","6"),"๗","7"),"๘","8"),"๙","9")) -> 2512 | M12: =SUBSTITUTE(SUBSTITUTE(SUBSTITUTE(SUBSTITUTE(_xlfn.TEXTBEFORE(SUBSTITUTE(SUBSTITUTE(SUBSTITUTE(SUBSTITUTE(SUBSTITUTE(SUBSTITUTE(SUBSTITUTE(SUBSTITUTE(SUBSTITUTE(SUBSTITUTE(_xlfn.TEXTAFTER(D12,"- "),"๐","0"),"๑","1"),"๒","2"),"๓","3"),"๔","4"),"๕","5"),"๖","6"),"๗","7"),"๘","8"),"๙","9"),","),"(",""),")",""),"-","")," ","") -> 0819976160 | N12: =_xlfn.TEXTBEFORE(_xlfn.TEXTAFTER(D12,CHAR(10)),CHAR(10)&"พระ") -> ม.๙ บ้านคำเกิ่ง ต.เตย อ.ม่วงสามสิบ จ.อุบลราชธานี ๓๔๑๔๐ | O12: =YEAR(TODAY())+543 - L12 -> 57 | P12: =VLOOKUP(T12,mapping!C:D,2,0) -> Y | Q12: =IFERROR("อ."&_xlfn.TEXTBEFORE(_xlfn.TEXTAFTER(N12,"อ.")," "),"") -> อ.ม่วงสามสิบ | R12: =IFERROR("จ."&_xlfn.TEXTBEFORE(_xlfn.TEXTAFTER(N12,"จ.")," "),"") -> จ.อุบลราชธานี | S12: =IF(LEFT(C12,4)="สาขา","B", IF(LEFT(C12,4)="สำรอ","R", IF(LEFT(C12,4)="สำรว","S",0))) -> B | T12: =S12&F12 -> B25
A13: =+A12+1 -> 11 | C13: สาขาที่ ๐๑๕ | D13: วัดป่าค้อเจริญธรรม ๒๓ หมู่ ๖ บ้านพืชอุดม ต.ปุเปื่อย อ.น้ำยืน จ.อุบลราชธานี ๓๔๓๒๐ พระครูวิบูลญาณคุณ (บรรจง กมโล) อุปสมบท เมื่ออายุ ๒๑ ปี วันที่ ๘ กุมภาพันธ์ ๒๕๑๓ (ผู้รับรอง) ๐๘๙๗๒๐ ๒๗๒๔,๐๔๕๓๗๑๑๔๒, | E13: =_xlfn.LET(_xlpm.x,C13, SUBSTITUTE(SUBSTITUTE(SUBSTITUTE(SUBSTITUTE(SUBSTITUTE( SUBSTITUTE(SUBSTITUTE(SUBSTITUTE(SUBSTITUTE(SUBSTITUTE( _xlpm.x,"๐","0"),"๑","1"),"๒","2"),"๓","3"),"๔","4"), "๕","5"),"๖","6"),"๗","7"),"๘","8"),"๙","9")) -> สาขาที่ 015 | F13: 15 | G13: =_xlfn.TEXTBEFORE(D13,CHAR(10)) -> วัดป่าค้อเจริญธรรม | H13: =TRIM(_xlfn.TEXTBEFORE(MID(D13,SEARCH("พระ",D13),100),CHAR(10))) -> พระครูวิบูลญาณคุณ (บรรจง กมโล) | I13: =VALUE(SUBSTITUTE(SUBSTITUTE(SUBSTITUTE(SUBSTITUTE(SUBSTITUTE(SUBSTITUTE(SUBSTITUTE(SUBSTITUTE(SUBSTITUTE(SUBSTITUTE(_xlfn.TEXTBEFORE(_xlfn.TEXTAFTER(D13,"เมื่ออายุ "), " ปี"),"๐","0"),"๑","1"),"๒","2"),"๓","3"),"๔","4"),"๕","5"),"๖","6"),"๗","7"),"๘","8"),"๙","9")) -> 21 | J13: =VALUE(SUBSTITUTE(SUBSTITUTE(SUBSTITUTE(SUBSTITUTE(SUBSTITUTE(SUBSTITUTE(SUBSTITUTE(SUBSTITUTE(SUBSTITUTE(SUBSTITUTE(_xlfn.TEXTBEFORE(_xlfn.TEXTAFTER(D13,"วันที่ "), " "),"๐","0"),"๑","1"),"๒","2"),"๓","3"),"๔","4"),"๕","5"),"๖","6"),"๗","7"),"๘","8"),"๙","9")) -> 8 | K13: =_xlfn.TEXTBEFORE(_xlfn.TEXTAFTER(D13,"วันที่ "&_xlfn.TEXTBEFORE(_xlfn.TEXTAFTER(D13,"วันที่ "), " ")&" "), " ") -> กุมภาพันธ์ | L13: =VALUE(SUBSTITUTE(SUBSTITUTE(SUBSTITUTE(SUBSTITUTE(SUBSTITUTE(SUBSTITUTE(SUBSTITUTE(SUBSTITUTE(SUBSTITUTE(SUBSTITUTE(_xlfn.TEXTBEFORE(_xlfn.TEXTAFTER(_xlfn.TEXTAFTER(D13,"วันที่ ")," "&_xlfn.TEXTBEFORE(_xlfn.TEXTAFTER(D13,"วันที่ "&_xlfn.TEXTBEFORE(_xlfn.TEXTAFTER(D13,"วันที่ "), " ")&" "), " ")&" "), " "),"๐","0"),"๑","1"),"๒","2"),"๓","3"),"๔","4"),"๕","5"),"๖","6"),"๗","7"),"๘","8"),"๙","9")) -> 2513 | M13: =SUBSTITUTE( _xlfn.TEXTBEFORE( SUBSTITUTE(SUBSTITUTE(SUBSTITUTE(SUBSTITUTE(SUBSTITUTE( SUBSTITUTE(SUBSTITUTE(SUBSTITUTE(SUBSTITUTE(SUBSTITUTE( _xlfn.TEXTAFTER(D13,CHAR(10),-1), "๐","0"),"๑","1"),"๒","2"),"๓","3"),"๔","4"), "๕","5"),"๖","6"),"๗","7"),"๘","8"),"๙","9"),",",-1)," ","") -> 0897202724,045371142 | N13: =_xlfn.TEXTBEFORE(_xlfn.TEXTAFTER(D13,CHAR(10)),CHAR(10)&"พระ") -> ๒๓ หมู่ ๖ บ้านพืชอุดม ต.ปุเปื่อย อ.น้ำยืน จ.อุบลราชธานี ๓๔๓๒๐ | O13: =YEAR(TODAY())+543 - L13 -> 56 | P13: =VLOOKUP(T13,mapping!C:D,2,0) -> Y | Q13: =IFERROR("อ."&_xlfn.TEXTBEFORE(_xlfn.TEXTAFTER(N13,"อ.")," "),"") -> อ.น้ำยืน | R13: =IFERROR("จ."&_xlfn.TEXTBEFORE(_xlfn.TEXTAFTER(N13,"จ.")," "),"") -> จ.อุบลราชธานี | S13: =IF(LEFT(C13,4)="สาขา","B", IF(LEFT(C13,4)="สำรอ","R", IF(LEFT(C13,4)="สำรว","S",0))) -> B | T13: =S13&F13 -> B15
A14: =+A13+1 -> 12 | C14: สาขาที่ ๒๙๒ | D14: วัดป่ากาญจนาราม ๑๙๙ ม.๓ บ้านอูนนา ต.นางัว อ.นาหว้า จ.นครพนม ๔๘๑๘๐ พระครูวิเวกธรรมานุกูล (ฉันท์ กตปุญฺโญ) อุปสมบท เมื่ออายุ ๒๒ ปี วันที่ ๒๓ เมษายน ๒๕๑๓ (ผู้รับรอง) - (๐๘๙) ๙๔๙-๑๒๘๘, | E14: =_xlfn.LET(_xlpm.x,C14, SUBSTITUTE(SUBSTITUTE(SUBSTITUTE(SUBSTITUTE(SUBSTITUTE( SUBSTITUTE(SUBSTITUTE(SUBSTITUTE(SUBSTITUTE(SUBSTITUTE( _xlpm.x,"๐","0"),"๑","1"),"๒","2"),"๓","3"),"๔","4"), "๕","5"),"๖","6"),"๗","7"),"๘","8"),"๙","9")) -> สาขาที่ 292 | F14: 292 | G14: =_xlfn.TEXTBEFORE(D14,CHAR(10)) -> วัดป่ากาญจนาราม | H14: =TRIM(_xlfn.TEXTBEFORE(MID(D14,SEARCH("พระ",D14),100),CHAR(10))) -> พระครูวิเวกธรรมานุกูล (ฉันท์ กตปุญฺโญ) | I14: =VALUE(SUBSTITUTE(SUBSTITUTE(SUBSTITUTE(SUBSTITUTE(SUBSTITUTE(SUBSTITUTE(SUBSTITUTE(SUBSTITUTE(SUBSTITUTE(SUBSTITUTE(_xlfn.TEXTBEFORE(_xlfn.TEXTAFTER(D14,"เมื่ออายุ "), " ปี"),"๐","0"),"๑","1"),"๒","2"),"๓","3"),"๔","4"),"๕","5"),"๖","6"),"๗","7"),"๘","8"),"๙","9")) -> 22 | J14: =VALUE(SUBSTITUTE(SUBSTITUTE(SUBSTITUTE(SUBSTITUTE(SUBSTITUTE(SUBSTITUTE(SUBSTITUTE(SUBSTITUTE(SUBSTITUTE(SUBSTITUTE(_xlfn.TEXTBEFORE(_xlfn.TEXTAFTER(D14,"วันที่ "), " "),"๐","0"),"๑","1"),"๒","2"),"๓","3"),"๔","4"),"๕","5"),"๖","6"),"๗","7"),"๘","8"),"๙","9")) -> 23 | K14: =_xlfn.TEXTBEFORE(_xlfn.TEXTAFTER(D14,"วันที่ "&_xlfn.TEXTBEFORE(_xlfn.TEXTAFTER(D14,"วันที่ "), " ")&" "), " ") -> เมษายน | L14: =VALUE(SUBSTITUTE(SUBSTITUTE(SUBSTITUTE(SUBSTITUTE(SUBSTITUTE(SUBSTITUTE(SUBSTITUTE(SUBSTITUTE(SUBSTITUTE(SUBSTITUTE(_xlfn.TEXTBEFORE(_xlfn.TEXTAFTER(_xlfn.TEXTAFTER(D14,"วันที่ ")," "&_xlfn.TEXTBEFORE(_xlfn.TEXTAFTER(D14,"วันที่ "&_xlfn.TEXTBEFORE(_xlfn.TEXTAFTER(D14,"วันที่ "), " ")&" "), " ")&" "), " "),"๐","0"),"๑","1"),"๒","2"),"๓","3"),"๔","4"),"๕","5"),"๖","6"),"๗","7"),"๘","8"),"๙","9")) -> 2513 | M14: =SUBSTITUTE(SUBSTITUTE(SUBSTITUTE(SUBSTITUTE(_xlfn.TEXTBEFORE(SUBSTITUTE(SUBSTITUTE(SUBSTITUTE(SUBSTITUTE(SUBSTITUTE(SUBSTITUTE(SUBSTITUTE(SUBSTITUTE(SUBSTITUTE(SUBSTITUTE(_xlfn.TEXTAFTER(D14,"- "),"๐","0"),"๑","1"),"๒","2"),"๓","3"),"๔","4"),"๕","5"),"๖","6"),"๗","7"),"๘","8"),"๙","9"),","),"(",""),")",""),"-","")," ","") -> 0899491288 | N14: =_xlfn.TEXTBEFORE(_xlfn.TEXTAFTER(D14,CHAR(10)),CHAR(10)&"พระ") -> ๑๙๙ ม.๓ บ้านอูนนา ต.นางัว อ.นาหว้า จ.นครพนม ๔๘๑๘๐ | O14: =YEAR(TODAY())+543 - L14 -> 56 | P14: =VLOOKUP(T14,mapping!C:D,2,0) -> Y | Q14: =IFERROR("อ."&_xlfn.TEXTBEFORE(_xlfn.TEXTAFTER(N14,"อ.")," "),"") -> อ.นาหว้า | R14: =IFERROR("จ."&_xlfn.TEXTBEFORE(_xlfn.TEXTAFTER(N14,"จ.")," "),"") -> จ.นครพนม | S14: =IF(LEFT(C14,4)="สาขา","B", IF(LEFT(C14,4)="สำรอ","R", IF(LEFT(C14,4)="สำรว","S",0))) -> B | T14: =S14&F14 -> B292
A15: =+A14+1 -> 13 | C15: สาขาที่ ๐๓๑ | D15: วัดอุดมวนาสันต์ ๓๖๗ ม.๒ บ้านนาเยีย ต.นาเยีย อ.นาเยีย จ.อุบลราชธานี ๓๔๑๖๐ พระครูอุดมวนานุรักษ์ (สมหมาย ปิยธมฺโม) อุปสมบท เมื่ออายุ ๒๐ ปี วันที่ ๒๑ มิถุนายน ๒๕๑๔ (ผู้รับรอง) - (๐๘๗) ๒๕๘-๕๒๔๕,๐๔๕๓๐๖๐๘๒, | E15: =_xlfn.LET(_xlpm.x,C15, SUBSTITUTE(SUBSTITUTE(SUBSTITUTE(SUBSTITUTE(SUBSTITUTE( SUBSTITUTE(SUBSTITUTE(SUBSTITUTE(SUBSTITUTE(SUBSTITUTE( _xlpm.x,"๐","0"),"๑","1"),"๒","2"),"๓","3"),"๔","4"), "๕","5"),"๖","6"),"๗","7"),"๘","8"),"๙","9")) -> สาขาที่ 031 | F15: 31 | G15: =_xlfn.TEXTBEFORE(D15,CHAR(10)) -> วัดอุดมวนาสันต์ | H15: =TRIM(_xlfn.TEXTBEFORE(MID(D15,SEARCH("พระ",D15),100),CHAR(10))) -> พระครูอุดมวนานุรักษ์ (สมหมาย ปิยธมฺโม) | I15: =VALUE(SUBSTITUTE(SUBSTITUTE(SUBSTITUTE(SUBSTITUTE(SUBSTITUTE(SUBSTITUTE(SUBSTITUTE(SUBSTITUTE(SUBSTITUTE(SUBSTITUTE(_xlfn.TEXTBEFORE(_xlfn.TEXTAFTER(D15,"เมื่ออายุ "), " ปี"),"๐","0"),"๑","1"),"๒","2"),"๓","3"),"๔","4"),"๕","5"),"๖","6"),"๗","7"),"๘","8"),"๙","9")) -> 20 | J15: =VALUE(SUBSTITUTE(SUBSTITUTE(SUBSTITUTE(SUBSTITUTE(SUBSTITUTE(SUBSTITUTE(SUBSTITUTE(SUBSTITUTE(SUBSTITUTE(SUBSTITUTE(_xlfn.TEXTBEFORE(_xlfn.TEXTAFTER(D15,"วันที่ "), " "),"๐","0"),"๑","1"),"๒","2"),"๓","3"),"๔","4"),"๕","5"),"๖","6"),"๗","7"),"๘","8"),"๙","9")) -> 21 | K15: =_xlfn.TEXTBEFORE(_xlfn.TEXTAFTER(D15,"วันที่ "&_xlfn.TEXTBEFORE(_xlfn.TEXTAFTER(D15,"วันที่ "), " ")&" "), " ") -> มิถุนายน | L15: =VALUE(SUBSTITUTE(SUBSTITUTE(SUBSTITUTE(SUBSTITUTE(SUBSTITUTE(SUBSTITUTE(SUBSTITUTE(SUBSTITUTE(SUBSTITUTE(SUBSTITUTE(_xlfn.TEXTBEFORE(_xlfn.TEXTAFTER(_xlfn.TEXTAFTER(D15,"วันที่ ")," "&_xlfn.TEXTBEFORE(_xlfn.TEXTAFTER(D15,"วันที่ "&_xlfn.TEXTBEFORE(_xlfn.TEXTAFTER(D15,"วันที่ "), " ")&" "), " ")&" "), " "),"๐","0"),"๑","1"),"๒","2"),"๓","3"),"๔","4"),"๕","5"),"๖","6"),"๗","7"),"๘","8"),"๙","9")) -> 2514 | M15: =SUBSTITUTE(SUBSTITUTE(SUBSTITUTE(SUBSTITUTE(_xlfn.TEXTBEFORE(SUBSTITUTE(SUBSTITUTE(SUBSTITUTE(SUBSTITUTE(SUBSTITUTE(SUBSTITUTE(SUBSTITUTE(SUBSTITUTE(SUBSTITUTE(SUBSTITUTE(_xlfn.TEXTAFTER(D15,"- "),"๐","0"),"๑","1"),"๒","2"),"๓","3"),"๔","4"),"๕","5"),"๖","6"),"๗","7"),"๘","8"),"๙","9"),","),"(",""),")",""),"-","")," ","") -> 0872585245 | N15: =_xlfn.TEXTBEFORE(_xlfn.TEXTAFTER(D15,CHAR(10)),CHAR(10)&"พระ") -> ๓๖๗ ม.๒ บ้านนาเยีย ต.นาเยีย อ.นาเยีย จ.อุบลราชธานี ๓๔๑๖๐ | O15: =YEAR(TODAY())+543 - L15 -> 55 | P15: =VLOOKUP(T15,mapping!C:D,2,0) -> Y | Q15: =IFERROR("อ."&_xlfn.TEXTBEFORE(_xlfn.TEXTAFTER(N15,"อ.")," "),"") -> อ.นาเยีย | R15: =IFERROR("จ."&_xlfn.TEXTBEFORE(_xlfn.TEXTAFTER(N15,"จ.")," "),"") -> จ.อุบลราชธานี | S15: =IF(LEFT(C15,4)="สาขา","B", IF(LEFT(C15,4)="สำรอ","R", IF(LEFT(C15,4)="สำรว","S",0))) -> B | T15: =S15&F15 -> B31
A16: =+A15+1 -> 14 | C16: สาขาที่ ๐๘๒ | D16: วัดเขาวันชัยนวรัตน์ ๗๖/๔ ม.๑๑ บ้านเกาะแก้ว ต.ปากช่อง อ.ปากช่อง จ.นครราชสีมา ๓๐๑๓๐ พระครูภาวนาอุดมคุณ (โสภา อุตฺตโม) อุปสมบท เมื่ออายุ ๒๕ ปี วันที่ ๖ เมษายน ๒๕๑๕ (ผู้รับรอง) ๐๘๑๘๗๙ ๓๒๘๘,- (๐๘๑) ๘๗๙-๓๒๘๘, | E16: =_xlfn.LET(_xlpm.x,C16, SUBSTITUTE(SUBSTITUTE(SUBSTITUTE(SUBSTITUTE(SUBSTITUTE( SUBSTITUTE(SUBSTITUTE(SUBSTITUTE(SUBSTITUTE(SUBSTITUTE( _xlpm.x,"๐","0"),"๑","1"),"๒","2"),"๓","3"),"๔","4"), "๕","5"),"๖","6"),"๗","7"),"๘","8"),"๙","9")) -> สาขาที่ 082 | F16: 82 | G16: =_xlfn.TEXTBEFORE(D16,CHAR(10)) -> วัดเขาวันชัยนวรัตน์ | H16: =TRIM(_xlfn.TEXTBEFORE(MID(D16,SEARCH("พระ",D16),100),CHAR(10))) -> พระครูภาวนาอุดมคุณ (โสภา อุตฺตโม) | I16: =VALUE(SUBSTITUTE(SUBSTITUTE(SUBSTITUTE(SUBSTITUTE(SUBSTITUTE(SUBSTITUTE(SUBSTITUTE(SUBSTITUTE(SUBSTITUTE(SUBSTITUTE(_xlfn.TEXTBEFORE(_xlfn.TEXTAFTER(D16,"เมื่ออายุ "), " ปี"),"๐","0"),"๑","1"),"๒","2"),"๓","3"),"๔","4"),"๕","5"),"๖","6"),"๗","7"),"๘","8"),"๙","9")) -> 25 | J16: =VALUE(SUBSTITUTE(SUBSTITUTE(SUBSTITUTE(SUBSTITUTE(SUBSTITUTE(SUBSTITUTE(SUBSTITUTE(SUBSTITUTE(SUBSTITUTE(SUBSTITUTE(_xlfn.TEXTBEFORE(_xlfn.TEXTAFTER(D16,"วันที่ "), " "),"๐","0"),"๑","1"),"๒","2"),"๓","3"),"๔","4"),"๕","5"),"๖","6"),"๗","7"),"๘","8"),"๙","9")) -> 6 | K16: =_xlfn.TEXTBEFORE(_xlfn.TEXTAFTER(D16,"วันที่ "&_xlfn.TEXTBEFORE(_xlfn.TEXTAFTER(D16,"วันที่ "), " ")&" "), " ") -> เมษายน | L16: =VALUE(SUBSTITUTE(SUBSTITUTE(SUBSTITUTE(SUBSTITUTE(SUBSTITUTE(SUBSTITUTE(SUBSTITUTE(SUBSTITUTE(SUBSTITUTE(SUBSTITUTE(_xlfn.TEXTBEFORE(_xlfn.TEXTAFTER(_xlfn.TEXTAFTER(D16,"วันที่ ")," "&_xlfn.TEXTBEFORE(_xlfn.TEXTAFTER(D16,"วันที่ "&_xlfn.TEXTBEFORE(_xlfn.TEXTAFTER(D16,"วันที่ "), " ")&" "), " ")&" "), " "),"๐","0"),"๑","1"),"๒","2"),"๓","3"),"๔","4"),"๕","5"),"๖","6"),"๗","7"),"๘","8"),"๙","9")) -> 2515 | M16: =SUBSTITUTE(SUBSTITUTE(SUBSTITUTE(SUBSTITUTE(_xlfn.TEXTBEFORE(SUBSTITUTE(SUBSTITUTE(SUBSTITUTE(SUBSTITUTE(SUBSTITUTE(SUBSTITUTE(SUBSTITUTE(SUBSTITUTE(SUBSTITUTE(SUBSTITUTE(_xlfn.TEXTAFTER(D16,"- "),"๐","0"),"๑","1"),"๒","2"),"๓","3"),"๔","4"),"๕","5"),"๖","6"),"๗","7"),"๘","8"),"๙","9"),","),"(",""),")",""),"-","")," ","") -> 0818793288 | N16: =_xlfn.TEXTBEFORE(_xlfn.TEXTAFTER(D16,CHAR(10)),CHAR(10)&"พระ") -> ๗๖/๔ ม.๑๑ บ้านเกาะแก้ว ต.ปากช่อง อ.ปากช่อง จ.นครราชสีมา ๓๐๑๓๐ | O16: =YEAR(TODAY())+543 - L16 -> 54 | P16: =VLOOKUP(T16,mapping!C:D,2,0) -> Y | Q16: =IFERROR("อ."&_xlfn.TEXTBEFORE(_xlfn.TEXTAFTER(N16,"อ.")," "),"") -> อ.ปากช่อง | R16: =IFERROR("จ."&_xlfn.TEXTBEFORE(_xlfn.TEXTAFTER(N16,"จ.")," "),"") -> จ.นครราชสีมา | S16: =IF(LEFT(C16,4)="สาขา","B", IF(LEFT(C16,4)="สำรอ","R", IF(LEFT(C16,4)="สำรว","S",0))) -> B | T16: =S16&F16 -> B82
A17: =+A16+1 -> 15 | C17: สาขาที่ ๐๑๒ | D17: วัดป่าหนองแวง ๒๔๔ หมู่ที่ ๔ บ้านหนองแวง ต.หนองแวง อ.กันทรารมย์ จ.ศรีสะเกษ ๓๓๑๓๐ พระครูนิมิตวิริยานุกูล (สุบิน อุตฺตโม) อุปสมบท เมื่ออายุ ๒๓ ปี วันที่ ๑๙ มกราคม ๒๕๑๖ (ผู้รับรอง) ๐๘๑๘๗๘ ๒๘๔๒, | E17: =_xlfn.LET(_xlpm.x,C17, SUBSTITUTE(SUBSTITUTE(SUBSTITUTE(SUBSTITUTE(SUBSTITUTE( SUBSTITUTE(SUBSTITUTE(SUBSTITUTE(SUBSTITUTE(SUBSTITUTE( _xlpm.x,"๐","0"),"๑","1"),"๒","2"),"๓","3"),"๔","4"), "๕","5"),"๖","6"),"๗","7"),"๘","8"),"๙","9")) -> สาขาที่ 012 | F17: 12 | G17: =_xlfn.TEXTBEFORE(D17,CHAR(10)) -> วัดป่าหนองแวง | H17: =TRIM(_xlfn.TEXTBEFORE(MID(D17,SEARCH("พระ",D17),100),CHAR(10))) -> พระครูนิมิตวิริยานุกูล (สุบิน อุตฺตโม) | I17: =VALUE(SUBSTITUTE(SUBSTITUTE(SUBSTITUTE(SUBSTITUTE(SUBSTITUTE(SUBSTITUTE(SUBSTITUTE(SUBSTITUTE(SUBSTITUTE(SUBSTITUTE(_xlfn.TEXTBEFORE(_xlfn.TEXTAFTER(D17,"เมื่ออายุ "), " ปี"),"๐","0"),"๑","1"),"๒","2"),"๓","3"),"๔","4"),"๕","5"),"๖","6"),"๗","7"),"๘","8"),"๙","9")) -> 23 | J17: =VALUE(SUBSTITUTE(SUBSTITUTE(SUBSTITUTE(SUBSTITUTE(SUBSTITUTE(SUBSTITUTE(SUBSTITUTE(SUBSTITUTE(SUBSTITUTE(SUBSTITUTE(_xlfn.TEXTBEFORE(_xlfn.TEXTAFTER(D17,"วันที่ "), " "),"๐","0"),"๑","1"),"๒","2"),"๓","3"),"๔","4"),"๕","5"),"๖","6"),"๗","7"),"๘","8"),"๙","9")) -> 19 | K17: =_xlfn.TEXTBEFORE(_xlfn.TEXTAFTER(D17,"วันที่ "&_xlfn.TEXTBEFORE(_xlfn.TEXTAFTER(D17,"วันที่ "), " ")&" "), " ") -> มกราคม | L17: =VALUE(SUBSTITUTE(SUBSTITUTE(SUBSTITUTE(SUBSTITUTE(SUBSTITUTE(SUBSTITUTE(SUBSTITUTE(SUBSTITUTE(SUBSTITUTE(SUBSTITUTE(_xlfn.TEXTBEFORE(_xlfn.TEXTAFTER(_xlfn.TEXTAFTER(D17,"วันที่ ")," "&_xlfn.TEXTBEFORE(_xlfn.TEXTAFTER(D17,"วันที่ "&_xlfn.TEXTBEFORE(_xlfn.TEXTAFTER(D17,"วันที่ "), " ")&" "), " ")&" "), " "),"๐","0"),"๑","1"),"๒","2"),"๓","3"),"๔","4"),"๕","5"),"๖","6"),"๗","7"),"๘","8"),"๙","9")) -> 2516 | M17: =SUBSTITUTE( _xlfn.TEXTBEFORE( SUBSTITUTE(SUBSTITUTE(SUBSTITUTE(SUBSTITUTE(SUBSTITUTE( SUBSTITUTE(SUBSTITUTE(SUBSTITUTE(SUBSTITUTE(SUBSTITUTE( _xlfn.TEXTAFTER(D17,CHAR(10),-1), "๐","0"),"๑","1"),"๒","2"),"๓","3"),"๔","4"), "๕","5"),"๖","6"),"๗","7"),"๘","8"),"๙","9"),",",-1)," ","") -> 0818782842 | N17: =_xlfn.TEXTBEFORE(_xlfn.TEXTAFTER(D17,CHAR(10)),CHAR(10)&"พระ") -> ๒๔๔ หมู่ที่ ๔ บ้านหนองแวง ต.หนองแวง อ.กันทรารมย์ จ.ศรีสะเกษ ๓๓๑๓๐ | O17: =YEAR(TODAY())+543 - L17 -> 53 | P17: =VLOOKUP(T17,mapping!C:D,2,0) -> Y | Q17: =IFERROR("อ."&_xlfn.TEXTBEFORE(_xlfn.TEXTAFTER(N17,"อ.")," "),"") -> อ.กันทรารมย์ | R17: =IFERROR("จ."&_xlfn.TEXTBEFORE(_xlfn.TEXTAFTER(N17,"จ.")," "),"") -> จ.ศรีสะเกษ | S17: =IF(LEFT(C17,4)="สาขา","B", IF(LEFT(C17,4)="สำรอ","R", IF(LEFT(C17,4)="สำรว","S",0))) -> B | T17: =S17&F17 -> B12
A18: =+A17+1 -> 16 | C18: สาขาที่ ๐๖๗ | D18: วัดป่าพิทักษ์ธรรม ๗๖ ม.๑๕ บ้านถาวรพัฒนา ต.นิคม อ.พิมาย จ.นครราชสีมา ๓๐๑๑๐ พระครูสุธรรมประโชติ (คำผอง ฐิตปุญโญ) อุปสมบท เมื่ออายุ ๒๓ ปี วันที่ ๒ มิถุนายน ๒๕๑๗ (ผู้รับรอง) - (๐๘๑) ๘๗๘-๐๓๔๑,- (๐๘๖) ๑๐๖-๓๑๓๓, | E18: =_xlfn.LET(_xlpm.x,C18, SUBSTITUTE(SUBSTITUTE(SUBSTITUTE(SUBSTITUTE(SUBSTITUTE( SUBSTITUTE(SUBSTITUTE(SUBSTITUTE(SUBSTITUTE(SUBSTITUTE( _xlpm.x,"๐","0"),"๑","1"),"๒","2"),"๓","3"),"๔","4"), "๕","5"),"๖","6"),"๗","7"),"๘","8"),"๙","9")) -> สาขาที่ 067 | F18: 67 | G18: =_xlfn.TEXTBEFORE(D18,CHAR(10)) -> วัดป่าพิทักษ์ธรรม | H18: =TRIM(_xlfn.TEXTBEFORE(MID(D18,SEARCH("พระ",D18),100),CHAR(10))) -> พระครูสุธรรมประโชติ (คำผอง ฐิตปุญโญ) | I18: =VALUE(SUBSTITUTE(SUBSTITUTE(SUBSTITUTE(SUBSTITUTE(SUBSTITUTE(SUBSTITUTE(SUBSTITUTE(SUBSTITUTE(SUBSTITUTE(SUBSTITUTE(_xlfn.TEXTBEFORE(_xlfn.TEXTAFTER(D18,"เมื่ออายุ "), " ปี"),"๐","0"),"๑","1"),"๒","2"),"๓","3"),"๔","4"),"๕","5"),"๖","6"),"๗","7"),"๘","8"),"๙","9")) -> 23 | J18: =VALUE(SUBSTITUTE(SUBSTITUTE(SUBSTITUTE(SUBSTITUTE(SUBSTITUTE(SUBSTITUTE(SUBSTITUTE(SUBSTITUTE(SUBSTITUTE(SUBSTITUTE(_xlfn.TEXTBEFORE(_xlfn.TEXTAFTER(D18,"วันที่ "), " "),"๐","0"),"๑","1"),"๒","2"),"๓","3"),"๔","4"),"๕","5"),"๖","6"),"๗","7"),"๘","8"),"๙","9")) -> 2 | K18: =_xlfn.TEXTBEFORE(_xlfn.TEXTAFTER(D18,"วันที่ "&_xlfn.TEXTBEFORE(_xlfn.TEXTAFTER(D18,"วันที่ "), " ")&" "), " ") -> มิถุนายน | L18: =VALUE(SUBSTITUTE(SUBSTITUTE(SUBSTITUTE(SUBSTITUTE(SUBSTITUTE(SUBSTITUTE(SUBSTITUTE(SUBSTITUTE(SUBSTITUTE(SUBSTITUTE(_xlfn.TEXTBEFORE(_xlfn.TEXTAFTER(_xlfn.TEXTAFTER(D18,"วันที่ ")," "&_xlfn.TEXTBEFORE(_xlfn.TEXTAFTER(D18,"วันที่ "&_xlfn.TEXTBEFORE(_xlfn.TEXTAFTER(D18,"วันที่ "), " ")&" "), " ")&" "), " "),"๐","0"),"๑","1"),"๒","2"),"๓","3"),"๔","4"),"๕","5"),"๖","6"),"๗","7"),"๘","8"),"๙","9")) -> 2517 | M18: =SUBSTITUTE(SUBSTITUTE(SUBSTITUTE(SUBSTITUTE(_xlfn.TEXTBEFORE(SUBSTITUTE(SUBSTITUTE(SUBSTITUTE(SUBSTITUTE(SUBSTITUTE(SUBSTITUTE(SUBSTITUTE(SUBSTITUTE(SUBSTITUTE(SUBSTITUTE(_xlfn.TEXTAFTER(D18,"- "),"๐","0"),"๑","1"),"๒","2"),"๓","3"),"๔","4"),"๕","5"),"๖","6"),"๗","7"),"๘","8"),"๙","9"),","),"(",""),")",""),"-","")," ","") -> 0818780341 | N18: =_xlfn.TEXTBEFORE(_xlfn.TEXTAFTER(D18,CHAR(10)),CHAR(10)&"พระ") -> ๗๖ ม.๑๕ บ้านถาวรพัฒนา ต.นิคม อ.พิมาย จ.นครราชสีมา ๓๐๑๑๐ | O18: =YEAR(TODAY())+543 - L18 -> 52 | P18: =VLOOKUP(T18,mapping!C:D,2,0) -> Y | Q18: =IFERROR("อ."&_xlfn.TEXTBEFORE(_xlfn.TEXTAFTER(N18,"อ.")," "),"") -> อ.พิมาย | R18: =IFERROR("จ."&_xlfn.TEXTBEFORE(_xlfn.TEXTAFTER(N18,"จ.")," "),"") -> จ.นครราชสีมา | S18: =IF(LEFT(C18,4)="สาขา","B", IF(LEFT(C18,4)="สำรอ","R", IF(LEFT(C18,4)="สำรว","S",0))) -> B | T18: =S18&F18 -> B67
A19: =+A18+1 -> 17 | C19: สาขาที่ ๑๔๔ | D19: วัดป่าดอนจิก (ดงตาปู่) ๓๗๑ หมู่ที่ ๑ ต.ดอนจิก อ.พิบูลมังสาหาร จ.อุบลราชธานี ๓๔๑๑๐ พระครูปลัดคำพันธ์ ฐิตธมฺโม อุปสมบท เมื่ออายุ ๒๕ ปี วันที่ ๒ มิถุนายน ๒๕๑๗ (ผู้รับรอง) - (๐๘๑) ๒๖๖-๐๖๙๑, | E19: =_xlfn.LET(_xlpm.x,C19, SUBSTITUTE(SUBSTITUTE(SUBSTITUTE(SUBSTITUTE(SUBSTITUTE( SUBSTITUTE(SUBSTITUTE(SUBSTITUTE(SUBSTITUTE(SUBSTITUTE( _xlpm.x,"๐","0"),"๑","1"),"๒","2"),"๓","3"),"๔","4"), "๕","5"),"๖","6"),"๗","7"),"๘","8"),"๙","9")) -> สาขาที่ 144 | F19: 144 | G19: =_xlfn.TEXTBEFORE(D19,CHAR(10)) -> วัดป่าดอนจิก (ดงตาปู่) | H19: =TRIM(_xlfn.TEXTBEFORE(MID(D19,SEARCH("พระ",D19),100),CHAR(10))) -> พระครูปลัดคำพันธ์ ฐิตธมฺโม | I19: =VALUE(SUBSTITUTE(SUBSTITUTE(SUBSTITUTE(SUBSTITUTE(SUBSTITUTE(SUBSTITUTE(SUBSTITUTE(SUBSTITUTE(SUBSTITUTE(SUBSTITUTE(_xlfn.TEXTBEFORE(_xlfn.TEXTAFTER(D19,"เมื่ออายุ "), " ปี"),"๐","0"),"๑","1"),"๒","2"),"๓","3"),"๔","4"),"๕","5"),"๖","6"),"๗","7"),"๘","8"),"๙","9")) -> 25 | J19: =VALUE(SUBSTITUTE(SUBSTITUTE(SUBSTITUTE(SUBSTITUTE(SUBSTITUTE(SUBSTITUTE(SUBSTITUTE(SUBSTITUTE(SUBSTITUTE(SUBSTITUTE(_xlfn.TEXTBEFORE(_xlfn.TEXTAFTER(D19,"วันที่ "), " "),"๐","0"),"๑","1"),"๒","2"),"๓","3"),"๔","4"),"๕","5"),"๖","6"),"๗","7"),"๘","8"),"๙","9")) -> 2 | K19: =_xlfn.TEXTBEFORE(_xlfn.TEXTAFTER(D19,"วันที่ "&_xlfn.TEXTBEFORE(_xlfn.TEXTAFTER(D19,"วันที่ "), " ")&" "), " ") -> มิถุนายน | L19: =VALUE(SUBSTITUTE(SUBSTITUTE(SUBSTITUTE(SUBSTITUTE(SUBSTITUTE(SUBSTITUTE(SUBSTITUTE(SUBSTITUTE(SUBSTITUTE(SUBSTITUTE(_xlfn.TEXTBEFORE(_xlfn.TEXTAFTER(_xlfn.TEXTAFTER(D19,"วันที่ ")," "&_xlfn.TEXTBEFORE(_xlfn.TEXTAFTER(D19,"วันที่ "&_xlfn.TEXTBEFORE(_xlfn.TEXTAFTER(D19,"วันที่ "), " ")&" "), " ")&" "), " "),"๐","0"),"๑","1"),"๒","2"),"๓","3"),"๔","4"),"๕","5"),"๖","6"),"๗","7"),"๘","8"),"๙","9")) -> 2517 | M19: =SUBSTITUTE(SUBSTITUTE(SUBSTITUTE(SUBSTITUTE(_xlfn.TEXTBEFORE(SUBSTITUTE(SUBSTITUTE(SUBSTITUTE(SUBSTITUTE(SUBSTITUTE(SUBSTITUTE(SUBSTITUTE(SUBSTITUTE(SUBSTITUTE(SUBSTITUTE(_xlfn.TEXTAFTER(D19,"- "),"๐","0"),"๑","1"),"๒","2"),"๓","3"),"๔","4"),"๕","5"),"๖","6"),"๗","7"),"๘","8"),"๙","9"),","),"(",""),")",""),"-","")," ","") -> 0812660691 | N19: =_xlfn.TEXTBEFORE(_xlfn.TEXTAFTER(D19,CHAR(10)),CHAR(10)&"พระ") -> ๓๗๑ หมู่ที่ ๑ ต.ดอนจิก อ.พิบูลมังสาหาร จ.อุบลราชธานี ๓๔๑๑๐ | O19: =YEAR(TODAY())+543 - L19 -> 52 | P19: =VLOOKUP(T19,mapping!C:D,2,0) -> Y | Q19: =IFERROR("อ."&_xlfn.TEXTBEFORE(_xlfn.TEXTAFTER(N19,"อ.")," "),"") -> อ.พิบูลมังสาหาร | R19: =IFERROR("จ."&_xlfn.TEXTBEFORE(_xlfn.TEXTAFTER(N19,"จ.")," "),"") -> จ.อุบลราชธานี | S19: =IF(LEFT(C19,4)="สาขา","B", IF(LEFT(C19,4)="สำรอ","R", IF(LEFT(C19,4)="สำรว","S",0))) -> B | T19: =S19&F19 -> B144
A20: =+A19+1 -> 18 | C20: สาขาที่ ๐๕๕ | D20: วัดป่าเขาหินตัด ๒๔/๙ ม.๕ บ้านคลองตะแบก ต.ลาดบัวขาว อ.สีคิ้ว จ.นครราชสีมา ๓๐๓๔๐ พระครูบรรพตบุญโญภาส (สมภาส อธิปุญฺโญ) อุปสมบท เมื่ออายุ ๒๑ ปี วันที่ ๒๐ กรกฎาคม ๒๕๑๘ (ผู้รับรอง) - (๐๘๑) ๙๖๗-๐๔๗๒, | E20: =_xlfn.LET(_xlpm.x,C20, SUBSTITUTE(SUBSTITUTE(SUBSTITUTE(SUBSTITUTE(SUBSTITUTE( SUBSTITUTE(SUBSTITUTE(SUBSTITUTE(SUBSTITUTE(SUBSTITUTE( _xlpm.x,"๐","0"),"๑","1"),"๒","2"),"๓","3"),"๔","4"), "๕","5"),"๖","6"),"๗","7"),"๘","8"),"๙","9")) -> สาขาที่ 055 | F20: 55 | G20: =_xlfn.TEXTBEFORE(D20,CHAR(10)) -> วัดป่าเขาหินตัด | H20: =TRIM(_xlfn.TEXTBEFORE(MID(D20,SEARCH("พระ",D20),100),CHAR(10))) -> พระครูบรรพตบุญโญภาส (สมภาส อธิปุญฺโญ) | I20: =VALUE(SUBSTITUTE(SUBSTITUTE(SUBSTITUTE(SUBSTITUTE(SUBSTITUTE(SUBSTITUTE(SUBSTITUTE(SUBSTITUTE(SUBSTITUTE(SUBSTITUTE(_xlfn.TEXTBEFORE(_xlfn.TEXTAFTER(D20,"เมื่ออายุ "), " ปี"),"๐","0"),"๑","1"),"๒","2"),"๓","3"),"๔","4"),"๕","5"),"๖","6"),"๗","7"),"๘","8"),"๙","9")) -> 21 | J20: =VALUE(SUBSTITUTE(SUBSTITUTE(SUBSTITUTE(SUBSTITUTE(SUBSTITUTE(SUBSTITUTE(SUBSTITUTE(SUBSTITUTE(SUBSTITUTE(SUBSTITUTE(_xlfn.TEXTBEFORE(_xlfn.TEXTAFTER(D20,"วันที่ "), " "),"๐","0"),"๑","1"),"๒","2"),"๓","3"),"๔","4"),"๕","5"),"๖","6"),"๗","7"),"๘","8"),"๙","9")) -> 20 | K20: =_xlfn.TEXTBEFORE(_xlfn.TEXTAFTER(D20,"วันที่ "&_xlfn.TEXTBEFORE(_xlfn.TEXTAFTER(D20,"วันที่ "), " ")&" "), " ") -> กรกฎาคม | L20: =VALUE(SUBSTITUTE(SUBSTITUTE(SUBSTITUTE(SUBSTITUTE(SUBSTITUTE(SUBSTITUTE(SUBSTITUTE(SUBSTITUTE(SUBSTITUTE(SUBSTITUTE(_xlfn.TEXTBEFORE(_xlfn.TEXTAFTER(_xlfn.TEXTAFTER(D20,"วันที่ ")," "&_xlfn.TEXTBEFORE(_xlfn.TEXTAFTER(D20,"วันที่ "&_xlfn.TEXTBEFORE(_xlfn.TEXTAFTER(D20,"วันที่ "), " ")&" "), " ")&" "), " "),"๐","0"),"๑","1"),"๒","2"),"๓","3"),"๔","4"),"๕","5"),"๖","6"),"๗","7"),"๘","8"),"๙","9")) -> 2518 | M20: =SUBSTITUTE(SUBSTITUTE(SUBSTITUTE(SUBSTITUTE(_xlfn.TEXTBEFORE(SUBSTITUTE(SUBSTITUTE(SUBSTITUTE(SUBSTITUTE(SUBSTITUTE(SUBSTITUTE(SUBSTITUTE(SUBSTITUTE(SUBSTITUTE(SUBSTITUTE(_xlfn.TEXTAFTER(D20,"- "),"๐","0"),"๑","1"),"๒","2"),"๓","3"),"๔","4"),"๕","5"),"๖","6"),"๗","7"),"๘","8"),"๙","9"),","),"(",""),")",""),"-","")," ","") -> 0819670472 | N20: =_xlfn.TEXTBEFORE(_xlfn.TEXTAFTER(D20,CHAR(10)),CHAR(10)&"พระ") -> ๒๔/๙ ม.๕ บ้านคลองตะแบก ต.ลาดบัวขาว อ.สีคิ้ว จ.นครราชสีมา ๓๐๓๔๐ | O20: =YEAR(TODAY())+543 - L20 -> 51 | P20: =VLOOKUP(T20,mapping!C:D,2,0) -> Y | Q20: =IFERROR("อ."&_xlfn.TEXTBEFORE(_xlfn.TEXTAFTER(N20,"อ.")," "),"") -> อ.สีคิ้ว | R20: =IFERROR("จ."&_xlfn.TEXTBEFORE(_xlfn.TEXTAFTER(N20,"จ.")," "),"") -> จ.นครราชสีมา | S20: =IF(LEFT(C20,4)="สาขา","B", IF(LEFT(C20,4)="สำรอ","R", IF(LEFT(C20,4)="สำรว","S",0))) -> B | T20: =S20&F20 -> B55
A21: =+A20+1 -> 19 | C21: สาขาที่ ๐๓๔ | D21: วัดเลิศสวัสดิ์ ( เขาจันทร์งาม ) ๙ ม.๑๒ บ้านเลิศสวัสดิ์ ต.ลาดบัวขาว อ.สีคิ้ว จ.นครราชสีมา ๓๐๓๔๐ พระครูบวรสีลวัตร (ประเสริฐ รกฺขิตสีโล) อุปสมบท เมื่ออายุ ๒๒ ปี วันที่ ๒๗ กุมภาพันธ์ ๒๕๑๘ (ผู้รับรอง) - (๐๘๗) ๒๕๒-๗๔๙๖, | E21: =_xlfn.LET(_xlpm.x,C21, SUBSTITUTE(SUBSTITUTE(SUBSTITUTE(SUBSTITUTE(SUBSTITUTE( SUBSTITUTE(SUBSTITUTE(SUBSTITUTE(SUBSTITUTE(SUBSTITUTE( _xlpm.x,"๐","0"),"๑","1"),"๒","2"),"๓","3"),"๔","4"), "๕","5"),"๖","6"),"๗","7"),"๘","8"),"๙","9")) -> สาขาที่ 034 | F21: 34 | G21: =_xlfn.TEXTBEFORE(D21,CHAR(10)) -> วัดเลิศสวัสดิ์ ( เขาจันทร์งาม ) | H21: =TRIM(_xlfn.TEXTBEFORE(MID(D21,SEARCH("พระ",D21),100),CHAR(10))) -> พระครูบวรสีลวัตร (ประเสริฐ รกฺขิตสีโล) | I21: =VALUE(SUBSTITUTE(SUBSTITUTE(SUBSTITUTE(SUBSTITUTE(SUBSTITUTE(SUBSTITUTE(SUBSTITUTE(SUBSTITUTE(SUBSTITUTE(SUBSTITUTE(_xlfn.TEXTBEFORE(_xlfn.TEXTAFTER(D21,"เมื่ออายุ "), " ปี"),"๐","0"),"๑","1"),"๒","2"),"๓","3"),"๔","4"),"๕","5"),"๖","6"),"๗","7"),"๘","8"),"๙","9")) -> 22 | J21: =VALUE(SUBSTITUTE(SUBSTITUTE(SUBSTITUTE(SUBSTITUTE(SUBSTITUTE(SUBSTITUTE(SUBSTITUTE(SUBSTITUTE(SUBSTITUTE(SUBSTITUTE(_xlfn.TEXTBEFORE(_xlfn.TEXTAFTER(D21,"วันที่ "), " "),"๐","0"),"๑","1"),"๒","2"),"๓","3"),"๔","4"),"๕","5"),"๖","6"),"๗","7"),"๘","8"),"๙","9")) -> 27 | K21: =_xlfn.TEXTBEFORE(_xlfn.TEXTAFTER(D21,"วันที่ "&_xlfn.TEXTBEFORE(_xlfn.TEXTAFTER(D21,"วันที่ "), " ")&" "), " ") -> กุมภาพันธ์ | L21: =VALUE(SUBSTITUTE(SUBSTITUTE(SUBSTITUTE(SUBSTITUTE(SUBSTITUTE(SUBSTITUTE(SUBSTITUTE(SUBSTITUTE(SUBSTITUTE(SUBSTITUTE(_xlfn.TEXTBEFORE(_xlfn.TEXTAFTER(_xlfn.TEXTAFTER(D21,"วันที่ ")," "&_xlfn.TEXTBEFORE(_xlfn.TEXTAFTER(D21,"วันที่ "&_xlfn.TEXTBEFORE(_xlfn.TEXTAFTER(D21,"วันที่ "), " ")&" "), " ")&" "), " "),"๐","0"),"๑","1"),"๒","2"),"๓","3"),"๔","4"),"๕","5"),"๖","6"),"๗","7"),"๘","8"),"๙","9")) -> 2518 | M21: =SUBSTITUTE(SUBSTITUTE(SUBSTITUTE(SUBSTITUTE(_xlfn.TEXTBEFORE(SUBSTITUTE(SUBSTITUTE(SUBSTITUTE(SUBSTITUTE(SUBSTITUTE(SUBSTITUTE(SUBSTITUTE(SUBSTITUTE(SUBSTITUTE(SUBSTITUTE(_xlfn.TEXTAFTER(D21,"- "),"๐","0"),"๑","1"),"๒","2"),"๓","3"),"๔","4"),"๕","5"),"๖","6"),"๗","7"),"๘","8"),"๙","9"),","),"(",""),")",""),"-","")," ","") -> 0872527496 | N21: =_xlfn.TEXTBEFORE(_xlfn.TEXTAFTER(D21,CHAR(10)),CHAR(10)&"พระ") -> ๙ ม.๑๒ บ้านเลิศสวัสดิ์ ต.ลาดบัวขาว อ.สีคิ้ว จ.นครราชสีมา ๓๐๓๔๐ | O21: =YEAR(TODAY())+543 - L21 -> 51 | P21: =VLOOKUP(T21,mapping!C:D,2,0) -> Y | Q21: =IFERROR("อ."&_xlfn.TEXTBEFORE(_xlfn.TEXTAFTER(N21,"อ.")," "),"") -> อ.สีคิ้ว | R21: =IFERROR("จ."&_xlfn.TEXTBEFORE(_xlfn.TEXTAFTER(N21,"จ.")," "),"") -> จ.นครราชสีมา | S21: =IF(LEFT(C21,4)="สาขา","B", IF(LEFT(C21,4)="สำรอ","R", IF(LEFT(C21,4)="สำรว","S",0))) -> B | T21: =S21&F21 -> B34
A22: =+A21+1 -> 20 | C22: สาขาที่ ๐๔๔ | D22: วัดป่าจิตตภาวนา ๕๐ ม.๕ ต.คูคต อ.ลำลูกกา จ.ปทุมธานี ๑๒๑๓๐ พระราชวชิรมุนี วิ. (ประสพไชย กนฺตสีโล) อุปสมบท เมื่ออายุ ๒๘ ปี วันที่ ๓ กรกฎาคม ๒๕๑๙ (ผู้รับรอง) ๐๒๕๓๒๑๕๔๘,- (๐๘๑) ๘๔๒-๖๖๙๕, | E22: =_xlfn.LET(_xlpm.x,C22, SUBSTITUTE(SUBSTITUTE(SUBSTITUTE(SUBSTITUTE(SUBSTITUTE( SUBSTITUTE(SUBSTITUTE(SUBSTITUTE(SUBSTITUTE(SUBSTITUTE( _xlpm.x,"๐","0"),"๑","1"),"๒","2"),"๓","3"),"๔","4"), "๕","5"),"๖","6"),"๗","7"),"๘","8"),"๙","9")) -> สาขาที่ 044 | F22: 44 | G22: =_xlfn.TEXTBEFORE(D22,CHAR(10)) -> วัดป่าจิตตภาวนา | H22: =TRIM(_xlfn.TEXTBEFORE(MID(D22,SEARCH("พระ",D22),100),CHAR(10))) -> พระราชวชิรมุนี วิ. (ประสพไชย กนฺตสีโล) | I22: =VALUE(SUBSTITUTE(SUBSTITUTE(SUBSTITUTE(SUBSTITUTE(SUBSTITUTE(SUBSTITUTE(SUBSTITUTE(SUBSTITUTE(SUBSTITUTE(SUBSTITUTE(_xlfn.TEXTBEFORE(_xlfn.TEXTAFTER(D22,"เมื่ออายุ "), " ปี"),"๐","0"),"๑","1"),"๒","2"),"๓","3"),"๔","4"),"๕","5"),"๖","6"),"๗","7"),"๘","8"),"๙","9")) -> 28 | J22: =VALUE(SUBSTITUTE(SUBSTITUTE(SUBSTITUTE(SUBSTITUTE(SUBSTITUTE(SUBSTITUTE(SUBSTITUTE(SUBSTITUTE(SUBSTITUTE(SUBSTITUTE(_xlfn.TEXTBEFORE(_xlfn.TEXTAFTER(D22,"วันที่ "), " "),"๐","0"),"๑","1"),"๒","2"),"๓","3"),"๔","4"),"๕","5"),"๖","6"),"๗","7"),"๘","8"),"๙","9")) -> 3 | K22: =_xlfn.TEXTBEFORE(_xlfn.TEXTAFTER(D22,"วันที่ "&_xlfn.TEXTBEFORE(_xlfn.TEXTAFTER(D22,"วันที่ "), " ")&" "), " ") -> กรกฎาคม | L22: =VALUE(SUBSTITUTE(SUBSTITUTE(SUBSTITUTE(SUBSTITUTE(SUBSTITUTE(SUBSTITUTE(SUBSTITUTE(SUBSTITUTE(SUBSTITUTE(SUBSTITUTE(_xlfn.TEXTBEFORE(_xlfn.TEXTAFTER(_xlfn.TEXTAFTER(D22,"วันที่ ")," "&_xlfn.TEXTBEFORE(_xlfn.TEXTAFTER(D22,"วันที่ "&_xlfn.TEXTBEFORE(_xlfn.TEXTAFTER(D22,"วันที่ "), " ")&" "), " ")&" "), " "),"๐","0"),"๑","1"),"๒","2"),"๓","3"),"๔","4"),"๕","5"),"๖","6"),"๗","7"),"๘","8"),"๙","9")) -> 2519 | M22: =SUBSTITUTE(SUBSTITUTE(SUBSTITUTE(SUBSTITUTE(_xlfn.TEXTBEFORE(SUBSTITUTE(SUBSTITUTE(SUBSTITUTE(SUBSTITUTE(SUBSTITUTE(SUBSTITUTE(SUBSTITUTE(SUBSTITUTE(SUBSTITUTE(SUBSTITUTE(_xlfn.TEXTAFTER(D22,"- "),"๐","0"),"๑","1"),"๒","2"),"๓","3"),"๔","4"),"๕","5"),"๖","6"),"๗","7"),"๘","8"),"๙","9"),","),"(",""),")",""),"-","")," ","") -> 0818426695 | N22: =_xlfn.TEXTBEFORE(_xlfn.TEXTAFTER(D22,CHAR(10)),CHAR(10)&"พระ") -> ๕๐ ม.๕ ต.คูคต อ.ลำลูกกา จ.ปทุมธานี ๑๒๑๓๐ | O22: =YEAR(TODAY())+543 - L22 -> 50 | P22: =VLOOKUP(T22,mapping!C:D,2,0) -> Y | Q22: =IFERROR("อ."&_xlfn.TEXTBEFORE(_xlfn.TEXTAFTER(N22,"อ.")," "),"") -> อ.ลำลูกกา | R22: =IFERROR("จ."&_xlfn.TEXTBEFORE(_xlfn.TEXTAFTER(N22,"จ.")," "),"") -> จ.ปทุมธานี | S22: =IF(LEFT(C22,4)="สาขา","B", IF(LEFT(C22,4)="สำรอ","R", IF(LEFT(C22,4)="สำรว","S",0))) -> B | T22: =S22&F22 -> B44
A23: =+A22+1 -> 21 | C23: สาขาที่ ๐๗๓ | D23: วัดมาบจันทร์ ๘/๑ ม.๗ บ้านมาบจันทร์ ต.แกลง อ.เมือง จ.ระยอง ๒๑๑๖๐ พระราชวชิรญาณ (อนันต์ อกิญฺจโน) วิ. ทป. จภ. ๑๓ อุปสมบท เมื่ออายุ ๒๒ ปี วันที่ ๓ กรกฎาคม ๒๕๑๙ (ผู้รับรอง) ๐๘๙๘๓๑ ๕๖๘๙,๐๘๑๙๑๕ ๕๖๔๓, | E23: =_xlfn.LET(_xlpm.x,C23, SUBSTITUTE(SUBSTITUTE(SUBSTITUTE(SUBSTITUTE(SUBSTITUTE( SUBSTITUTE(SUBSTITUTE(SUBSTITUTE(SUBSTITUTE(SUBSTITUTE( _xlpm.x,"๐","0"),"๑","1"),"๒","2"),"๓","3"),"๔","4"), "๕","5"),"๖","6"),"๗","7"),"๘","8"),"๙","9")) -> สาขาที่ 073 | F23: 73 | G23: =_xlfn.TEXTBEFORE(D23,CHAR(10)) -> วัดมาบจันทร์ | H23: =TRIM(_xlfn.TEXTBEFORE(MID(D23,SEARCH("พระ",D23),100),CHAR(10))) -> พระราชวชิรญาณ (อนันต์ อกิญฺจโน) วิ. ทป. จภ. ๑๓ | I23: =VALUE(SUBSTITUTE(SUBSTITUTE(SUBSTITUTE(SUBSTITUTE(SUBSTITUTE(SUBSTITUTE(SUBSTITUTE(SUBSTITUTE(SUBSTITUTE(SUBSTITUTE(_xlfn.TEXTBEFORE(_xlfn.TEXTAFTER(D23,"เมื่ออายุ "), " ปี"),"๐","0"),"๑","1"),"๒","2"),"๓","3"),"๔","4"),"๕","5"),"๖","6"),"๗","7"),"๘","8"),"๙","9")) -> 22 | J23: =VALUE(SUBSTITUTE(SUBSTITUTE(SUBSTITUTE(SUBSTITUTE(SUBSTITUTE(SUBSTITUTE(SUBSTITUTE(SUBSTITUTE(SUBSTITUTE(SUBSTITUTE(_xlfn.TEXTBEFORE(_xlfn.TEXTAFTER(D23,"วันที่ "), " "),"๐","0"),"๑","1"),"๒","2"),"๓","3"),"๔","4"),"๕","5"),"๖","6"),"๗","7"),"๘","8"),"๙","9")) -> 3 | K23: =_xlfn.TEXTBEFORE(_xlfn.TEXTAFTER(D23,"วันที่ "&_xlfn.TEXTBEFORE(_xlfn.TEXTAFTER(D23,"วันที่ "), " ")&" "), " ") -> กรกฎาคม | L23: =VALUE(SUBSTITUTE(SUBSTITUTE(SUBSTITUTE(SUBSTITUTE(SUBSTITUTE(SUBSTITUTE(SUBSTITUTE(SUBSTITUTE(SUBSTITUTE(SUBSTITUTE(_xlfn.TEXTBEFORE(_xlfn.TEXTAFTER(_xlfn.TEXTAFTER(D23,"วันที่ ")," "&_xlfn.TEXTBEFORE(_xlfn.TEXTAFTER(D23,"วันที่ "&_xlfn.TEXTBEFORE(_xlfn.TEXTAFTER(D23,"วันที่ "), " ")&" "), " ")&" "), " "),"๐","0"),"๑","1"),"๒","2"),"๓","3"),"๔","4"),"๕","5"),"๖","6"),"๗","7"),"๘","8"),"๙","9")) -> 2519 | M23: =SUBSTITUTE( _xlfn.TEXTBEFORE( SUBSTITUTE(SUBSTITUTE(SUBSTITUTE(SUBSTITUTE(SUBSTITUTE( SUBSTITUTE(SUBSTITUTE(SUBSTITUTE(SUBSTITUTE(SUBSTITUTE( _xlfn.TEXTAFTER(D23,CHAR(10),-1), "๐","0"),"๑","1"),"๒","2"),"๓","3"),"๔","4"), "๕","5"),"๖","6"),"๗","7"),"๘","8"),"๙","9"),",",-1)," ","") -> 0898315689,0819155643 | N23: =_xlfn.TEXTBEFORE(_xlfn.TEXTAFTER(D23,CHAR(10)),CHAR(10)&"พระ") -> ๘/๑ ม.๗ บ้านมาบจันทร์ ต.แกลง อ.เมือง จ.ระยอง ๒๑๑๖๐ | O23: =YEAR(TODAY())+543 - L23 -> 50 | P23: =VLOOKUP(T23,mapping!C:D,2,0) -> Y | Q23: =IFERROR("อ."&_xlfn.TEXTBEFORE(_xlfn.TEXTAFTER(N23,"อ.")," "),"") -> อ.เมือง | R23: =IFERROR("จ."&_xlfn.TEXTBEFORE(_xlfn.TEXTAFTER(N23,"จ.")," "),"") -> จ.ระยอง | S23: =IF(LEFT(C23,4)="สาขา","B", IF(LEFT(C23,4)="สำรอ","R", IF(LEFT(C23,4)="สำรว","S",0))) -> B | T23: =S23&F23 -> B73
A24: =+A23+1 -> 22 | C24: สาขาที่ ๑๒๓ | D24: วัดภูคำ ๒๐๕ ม.๑๐ บ้านภูคำ ต.ภูเงิน อ.กันทรลักษ์ จ.ศรีสะเกษ ๓๓๑๑๐ พระอธิการสุภาพ สุภาจาโร อุปสมบท เมื่ออายุ ๒๒ ปี วันที่ ๒๔ พฤษภาคม ๒๕๑๙ (ผู้รับรอง) - (๐๘๑) ๐๖๒-๒๒๐๓, | E24: =_xlfn.LET(_xlpm.x,C24, SUBSTITUTE(SUBSTITUTE(SUBSTITUTE(SUBSTITUTE(SUBSTITUTE( SUBSTITUTE(SUBSTITUTE(SUBSTITUTE(SUBSTITUTE(SUBSTITUTE( _xlpm.x,"๐","0"),"๑","1"),"๒","2"),"๓","3"),"๔","4"), "๕","5"),"๖","6"),"๗","7"),"๘","8"),"๙","9")) -> สาขาที่ 123 | F24: 123 | G24: =_xlfn.TEXTBEFORE(D24,CHAR(10)) -> วัดภูคำ | H24: =TRIM(_xlfn.TEXTBEFORE(MID(D24,SEARCH("พระ",D24),100),CHAR(10))) -> พระอธิการสุภาพ สุภาจาโร | I24: =VALUE(SUBSTITUTE(SUBSTITUTE(SUBSTITUTE(SUBSTITUTE(SUBSTITUTE(SUBSTITUTE(SUBSTITUTE(SUBSTITUTE(SUBSTITUTE(SUBSTITUTE(_xlfn.TEXTBEFORE(_xlfn.TEXTAFTER(D24,"เมื่ออายุ "), " ปี"),"๐","0"),"๑","1"),"๒","2"),"๓","3"),"๔","4"),"๕","5"),"๖","6"),"๗","7"),"๘","8"),"๙","9")) -> 22 | J24: =VALUE(SUBSTITUTE(SUBSTITUTE(SUBSTITUTE(SUBSTITUTE(SUBSTITUTE(SUBSTITUTE(SUBSTITUTE(SUBSTITUTE(SUBSTITUTE(SUBSTITUTE(_xlfn.TEXTBEFORE(_xlfn.TEXTAFTER(D24,"วันที่ "), " "),"๐","0"),"๑","1"),"๒","2"),"๓","3"),"๔","4"),"๕","5"),"๖","6"),"๗","7"),"๘","8"),"๙","9")) -> 24 | K24: =_xlfn.TEXTBEFORE(_xlfn.TEXTAFTER(D24,"วันที่ "&_xlfn.TEXTBEFORE(_xlfn.TEXTAFTER(D24,"วันที่ "), " ")&" "), " ") -> พฤษภาคม | L24: =VALUE(SUBSTITUTE(SUBSTITUTE(SUBSTITUTE(SUBSTITUTE(SUBSTITUTE(SUBSTITUTE(SUBSTITUTE(SUBSTITUTE(SUBSTITUTE(SUBSTITUTE(_xlfn.TEXTBEFORE(_xlfn.TEXTAFTER(_xlfn.TEXTAFTER(D24,"วันที่ ")," "&_xlfn.TEXTBEFORE(_xlfn.TEXTAFTER(D24,"วันที่ "&_xlfn.TEXTBEFORE(_xlfn.TEXTAFTER(D24,"วันที่ "), " ")&" "), " ")&" "), " "),"๐","0"),"๑","1"),"๒","2"),"๓","3"),"๔","4"),"๕","5"),"๖","6"),"๗","7"),"๘","8"),"๙","9")) -> 2519 | M24: =SUBSTITUTE(SUBSTITUTE(SUBSTITUTE(SUBSTITUTE(_xlfn.TEXTBEFORE(SUBSTITUTE(SUBSTITUTE(SUBSTITUTE(SUBSTITUTE(SUBSTITUTE(SUBSTITUTE(SUBSTITUTE(SUBSTITUTE(SUBSTITUTE(SUBSTITUTE(_xlfn.TEXTAFTER(D24,"- "),"๐","0"),"๑","1"),"๒","2"),"๓","3"),"๔","4"),"๕","5"),"๖","6"),"๗","7"),"๘","8"),"๙","9"),","),"(",""),")",""),"-","")," ","") -> 0810622203 | N24: =_xlfn.TEXTBEFORE(_xlfn.TEXTAFTER(D24,CHAR(10)),CHAR(10)&"พระ") -> ๒๐๕ ม.๑๐ บ้านภูคำ ต.ภูเงิน อ.กันทรลักษ์ จ.ศรีสะเกษ ๓๓๑๑๐ | O24: =YEAR(TODAY())+543 - L24 -> 50 | P24: =VLOOKUP(T24,mapping!C:D,2,0) -> Y | Q24: =IFERROR("อ."&_xlfn.TEXTBEFORE(_xlfn.TEXTAFTER(N24,"อ.")," "),"") -> อ.กันทรลักษ์ | R24: =IFERROR("จ."&_xlfn.TEXTBEFORE(_xlfn.TEXTAFTER(N24,"จ.")," "),"") -> จ.ศรีสะเกษ | S24: =IF(LEFT(C24,4)="สาขา","B", IF(LEFT(C24,4)="สำรอ","R", IF(LEFT(C24,4)="สำรว","S",0))) -> B | T24: =S24&F24 -> B123
A25: =+A24+1 -> 23 | C25: สาขาที่ ๑๙๖ | D25: วัดป่าภูสิงห์ ๑๙๙ ม.๙ บ้านตะแบงใต้ ต.ห้วยตึ้กชู อ.ภูสิงห์ จ.ศรีสะเกษ ๓๓๑๔๐ พระครูสุตธรรมาภิวัฒน์ (คำทูล กมฺพุทตฺโต) อุปสมบท เมื่ออายุ ๒๑ ปี วันที่ ๕ ธันวาคม ๒๕๑๙ (ผู้รับรอง) - (๐๘๓) ๑๐๑-๔๓๕๖,๐๔๕๖๐๘๐๙๗, | E25: =_xlfn.LET(_xlpm.x,C25, SUBSTITUTE(SUBSTITUTE(SUBSTITUTE(SUBSTITUTE(SUBSTITUTE( SUBSTITUTE(SUBSTITUTE(SUBSTITUTE(SUBSTITUTE(SUBSTITUTE( _xlpm.x,"๐","0"),"๑","1"),"๒","2"),"๓","3"),"๔","4"), "๕","5"),"๖","6"),"๗","7"),"๘","8"),"๙","9")) -> สาขาที่ 196 | F25: 196 | G25: =_xlfn.TEXTBEFORE(D25,CHAR(10)) -> วัดป่าภูสิงห์ | H25: =TRIM(_xlfn.TEXTBEFORE(MID(D25,SEARCH("พระ",D25),100),CHAR(10))) -> พระครูสุตธรรมาภิวัฒน์ (คำทูล กมฺพุทตฺโต) | I25: =VALUE(SUBSTITUTE(SUBSTITUTE(SUBSTITUTE(SUBSTITUTE(SUBSTITUTE(SUBSTITUTE(SUBSTITUTE(SUBSTITUTE(SUBSTITUTE(SUBSTITUTE(_xlfn.TEXTBEFORE(_xlfn.TEXTAFTER(D25,"เมื่ออายุ "), " ปี"),"๐","0"),"๑","1"),"๒","2"),"๓","3"),"๔","4"),"๕","5"),"๖","6"),"๗","7"),"๘","8"),"๙","9")) -> 21 | J25: =VALUE(SUBSTITUTE(SUBSTITUTE(SUBSTITUTE(SUBSTITUTE(SUBSTITUTE(SUBSTITUTE(SUBSTITUTE(SUBSTITUTE(SUBSTITUTE(SUBSTITUTE(_xlfn.TEXTBEFORE(_xlfn.TEXTAFTER(D25,"วันที่ "), " "),"๐","0"),"๑","1"),"๒","2"),"๓","3"),"๔","4"),"๕","5"),"๖","6"),"๗","7"),"๘","8"),"๙","9")) -> 5 | K25: =_xlfn.TEXTBEFORE(_xlfn.TEXTAFTER(D25,"วันที่ "&_xlfn.TEXTBEFORE(_xlfn.TEXTAFTER(D25,"วันที่ "), " ")&" "), " ") -> ธันวาคม | L25: =VALUE(SUBSTITUTE(SUBSTITUTE(SUBSTITUTE(SUBSTITUTE(SUBSTITUTE(SUBSTITUTE(SUBSTITUTE(SUBSTITUTE(SUBSTITUTE(SUBSTITUTE(_xlfn.TEXTBEFORE(_xlfn.TEXTAFTER(_xlfn.TEXTAFTER(D25,"วันที่ ")," "&_xlfn.TEXTBEFORE(_xlfn.TEXTAFTER(D25,"วันที่ "&_xlfn.TEXTBEFORE(_xlfn.TEXTAFTER(D25,"วันที่ "), " ")&" "), " ")&" "), " "),"๐","0"),"๑","1"),"๒","2"),"๓","3"),"๔","4"),"๕","5"),"๖","6"),"๗","7"),"๘","8"),"๙","9")) -> 2519 | M25: =SUBSTITUTE(SUBSTITUTE(SUBSTITUTE(SUBSTITUTE(_xlfn.TEXTBEFORE(SUBSTITUTE(SUBSTITUTE(SUBSTITUTE(SUBSTITUTE(SUBSTITUTE(SUBSTITUTE(SUBSTITUTE(SUBSTITUTE(SUBSTITUTE(SUBSTITUTE(_xlfn.TEXTAFTER(D25,"- "),"๐","0"),"๑","1"),"๒","2"),"๓","3"),"๔","4"),"๕","5"),"๖","6"),"๗","7"),"๘","8"),"๙","9"),","),"(",""),")",""),"-","")," ","") -> 0831014356 | N25: =_xlfn.TEXTBEFORE(_xlfn.TEXTAFTER(D25,CHAR(10)),CHAR(10)&"พระ") -> ๑๙๙ ม.๙ บ้านตะแบงใต้ ต.ห้วยตึ้กชู อ.ภูสิงห์ จ.ศรีสะเกษ ๓๓๑๔๐ | O25: =YEAR(TODAY())+543 - L25 -> 50 | P25: =VLOOKUP(T25,mapping!C:D,2,0) -> Y | Q25: =IFERROR("อ."&_xlfn.TEXTBEFORE(_xlfn.TEXTAFTER(N25,"อ.")," "),"") -> อ.ภูสิงห์ | R25: =IFERROR("จ."&_xlfn.TEXTBEFORE(_xlfn.TEXTAFTER(N25,"จ.")," "),"") -> จ.ศรีสะเกษ | S25: =IF(LEFT(C25,4)="สาขา","B", IF(LEFT(C25,4)="สำรอ","R", IF(LEFT(C25,4)="สำรว","S",0))) -> B | T25: =S25&F25 -> B196
